{
 "cells": [
  {
   "cell_type": "code",
   "execution_count": 7,
   "metadata": {},
   "outputs": [],
   "source": [
    "from selenium import webdriver\n",
    "from selenium.webdriver.support.ui import Select\n",
    "from selenium.webdriver.common.by import By\n",
    "\n",
    "from selenium import webdriver\n",
    "from selenium.webdriver.chrome.service import Service\n",
    "from webdriver_manager.chrome import ChromeDriverManager\n",
    "driver = webdriver.Chrome(service=Service(ChromeDriverManager().install()))\n",
    "\n",
    "from re import search\n",
    "\n",
    "\n",
    "import requests\n",
    "from bs4 import BeautifulSoup\n",
    "\n",
    "'''\n",
    "NAVER 크롤링\n",
    "'''\n",
    "\n",
    "def naver_crawling():\n",
    "    URL = 'https://terms.naver.com/entry.naver?docId=1125333&cid=40942&categoryId=34081'\n",
    "    response = requests.get(URL)\n",
    "    soup =BeautifulSoup(response.text, 'html.parser')\n",
    "\n",
    "    spain_tbody = soup.select_one('tbody')\n",
    "    trs = spain_tbody.select('tr')\n",
    "    \n",
    "    spain_result = {}\n",
    "\n",
    "    for tr in trs:\n",
    "\n",
    "        spain_title = tr.select('th > span')[0].text.strip()\n",
    "        spain_data = tr.select('td')[0].text.strip()\n",
    "        \n",
    "        spain_result.setdefault(spain_title, spain_data)\n",
    "        \n",
    "        spain_result\n",
    "        final_result='원어명: '+ spain_result['원어명'] + '위치: '+ spain_result['위치']+ '시간대: '+spain_result['시간대'] +'면적(㎢): '+ spain_result['면적(㎢)']+'시간대: '+spain_result['시간대']+'수도: '+spain_result['수도']+'종족구성: '+spain_result['종족구성']+'국제전화: '+spain_result['국제전화']\n",
    "        return(final_result)\n",
    "\n",
    "# 결과물 한글로 변환 어케하는지\n",
    "\n",
    "\n",
    "'''\n",
    "EBS 크롤링 \n",
    "'''\n",
    "\n",
    "def ebs_crawling():\n",
    "\n",
    "    url = 'https://worldtrip.ebs.co.kr/worldtrip/main'\n",
    "    driver.get(url)\n",
    "\n",
    "\n",
    "    # 파이썬 셀레니움 드롭다운 박스 선택\n",
    "    # 셀레니움 드롭다운 select tag xpath로 크롤링 \n",
    "\n",
    "    driver.implicitly_wait(3)\n",
    "    dropdown = Select(driver.find_element(By.ID,'catgry1'))  #정렬기준 드롭다운\n",
    "    dropdown.select_by_visible_text('세계테마기행')\n",
    "\n",
    "    driver.implicitly_wait(3)\n",
    "    dropdown2 = Select(driver.find_element(By.ID,'catgry2'))\n",
    "    dropdown2.select_by_visible_text('유럽')\n",
    "\n",
    "    driver.implicitly_wait(3)\n",
    "    dropdown3 = Select(driver.find_element(By.ID,'catgry3'))\n",
    "    dropdown3.select_by_visible_text('스페인')\n",
    "\n",
    "\n",
    "    driver.implicitly_wait(3)\n",
    "    # search = driver.find_element(By.CLASS_NAME, 'submit')\n",
    "    # driver.click()\n",
    "    try:\n",
    "        driver.find_element(By.CSS_SELECTOR, 'a[onclick^=\"catgrySearch( this )\"]').click() \n",
    "    except:\n",
    "        driver.find_element(By.CSS_SELECTOR, 'a[onclick^=\"catgrySearch(this)\"]').click()\n",
    "\n",
    "    element = driver.find_element(By.XPATH, '//*[@id=\"vodList\"]/li[1]/a/span/span/span[1]')\n",
    "\n",
    "    elements = driver.find_elements(By.CSS_SELECTOR, '#vodList > li > a')\n",
    "\n",
    "    elements=elements[:3]\n",
    "\n",
    "    vod_list = []\n",
    "\n",
    "    for element in elements:\n",
    "        title = element.text\n",
    "        link = element.get_attribute('href')\n",
    "\n",
    "    #print(title,link)\n",
    "\n",
    "        temp = {}\n",
    "        temp['동영상 제목'] = title\n",
    "        temp['링크'] = link\n",
    "\n",
    "        vod_list.append(temp)\n",
    "\n",
    "        return(vod_list)\n"
   ]
  },
  {
   "cell_type": "code",
   "execution_count": 8,
   "metadata": {},
   "outputs": [],
   "source": [
    "import telegram \n",
    "import requests\n",
    "from telegram.ext import Updater\n",
    "from telegram.ext import MessageHandler, Filters\n"
   ]
  },
  {
   "cell_type": "code",
   "execution_count": 9,
   "metadata": {},
   "outputs": [
    {
     "name": "stderr",
     "output_type": "stream",
     "text": [
      "Error while getting Updates: Conflict: terminated by other getUpdates request; make sure that only one bot instance is running\n",
      "No error handlers are registered, logging exception.\n",
      "Traceback (most recent call last):\n",
      "  File \"c:\\Users\\virtue\\anaconda3\\envs\\study\\lib\\site-packages\\telegram\\ext\\updater.py\", line 651, in _network_loop_retry\n",
      "    if not action_cb():\n",
      "  File \"c:\\Users\\virtue\\anaconda3\\envs\\study\\lib\\site-packages\\telegram\\ext\\updater.py\", line 602, in polling_action_cb\n",
      "    updates = self.bot.get_updates(\n",
      "  File \"c:\\Users\\virtue\\anaconda3\\envs\\study\\lib\\site-packages\\telegram\\ext\\extbot.py\", line 226, in get_updates\n",
      "    updates = super().get_updates(\n",
      "  File \"c:\\Users\\virtue\\anaconda3\\envs\\study\\lib\\site-packages\\telegram\\bot.py\", line 133, in decorator\n",
      "    result = func(*args, **kwargs)\n",
      "  File \"c:\\Users\\virtue\\anaconda3\\envs\\study\\lib\\site-packages\\telegram\\bot.py\", line 3057, in get_updates\n",
      "    self._post(\n",
      "  File \"c:\\Users\\virtue\\anaconda3\\envs\\study\\lib\\site-packages\\telegram\\bot.py\", line 298, in _post\n",
      "    return self.request.post(\n",
      "  File \"c:\\Users\\virtue\\anaconda3\\envs\\study\\lib\\site-packages\\telegram\\utils\\request.py\", line 361, in post\n",
      "    result = self._request_wrapper(\n",
      "  File \"c:\\Users\\virtue\\anaconda3\\envs\\study\\lib\\site-packages\\telegram\\utils\\request.py\", line 283, in _request_wrapper\n",
      "    raise Conflict(message)\n",
      "telegram.error.Conflict: Conflict: terminated by other getUpdates request; make sure that only one bot instance is running\n"
     ]
    },
    {
     "name": "stderr",
     "output_type": "stream",
     "text": [
      "Error while getting Updates: Conflict: terminated by other getUpdates request; make sure that only one bot instance is running\n",
      "No error handlers are registered, logging exception.\n",
      "Traceback (most recent call last):\n",
      "  File \"c:\\Users\\virtue\\anaconda3\\envs\\study\\lib\\site-packages\\telegram\\ext\\updater.py\", line 651, in _network_loop_retry\n",
      "    if not action_cb():\n",
      "  File \"c:\\Users\\virtue\\anaconda3\\envs\\study\\lib\\site-packages\\telegram\\ext\\updater.py\", line 602, in polling_action_cb\n",
      "    updates = self.bot.get_updates(\n",
      "  File \"c:\\Users\\virtue\\anaconda3\\envs\\study\\lib\\site-packages\\telegram\\ext\\extbot.py\", line 226, in get_updates\n",
      "    updates = super().get_updates(\n",
      "  File \"c:\\Users\\virtue\\anaconda3\\envs\\study\\lib\\site-packages\\telegram\\bot.py\", line 133, in decorator\n",
      "    result = func(*args, **kwargs)\n",
      "  File \"c:\\Users\\virtue\\anaconda3\\envs\\study\\lib\\site-packages\\telegram\\bot.py\", line 3057, in get_updates\n",
      "    self._post(\n",
      "  File \"c:\\Users\\virtue\\anaconda3\\envs\\study\\lib\\site-packages\\telegram\\bot.py\", line 298, in _post\n",
      "    return self.request.post(\n",
      "  File \"c:\\Users\\virtue\\anaconda3\\envs\\study\\lib\\site-packages\\telegram\\utils\\request.py\", line 361, in post\n",
      "    result = self._request_wrapper(\n",
      "  File \"c:\\Users\\virtue\\anaconda3\\envs\\study\\lib\\site-packages\\telegram\\utils\\request.py\", line 283, in _request_wrapper\n",
      "    raise Conflict(message)\n",
      "telegram.error.Conflict: Conflict: terminated by other getUpdates request; make sure that only one bot instance is running\n",
      "Error while getting Updates: Conflict: terminated by other getUpdates request; make sure that only one bot instance is running\n",
      "No error handlers are registered, logging exception.\n",
      "Traceback (most recent call last):\n",
      "  File \"c:\\Users\\virtue\\anaconda3\\envs\\study\\lib\\site-packages\\telegram\\ext\\updater.py\", line 651, in _network_loop_retry\n",
      "    if not action_cb():\n",
      "  File \"c:\\Users\\virtue\\anaconda3\\envs\\study\\lib\\site-packages\\telegram\\ext\\updater.py\", line 602, in polling_action_cb\n",
      "    updates = self.bot.get_updates(\n",
      "  File \"c:\\Users\\virtue\\anaconda3\\envs\\study\\lib\\site-packages\\telegram\\ext\\extbot.py\", line 226, in get_updates\n",
      "    updates = super().get_updates(\n",
      "  File \"c:\\Users\\virtue\\anaconda3\\envs\\study\\lib\\site-packages\\telegram\\bot.py\", line 133, in decorator\n",
      "    result = func(*args, **kwargs)\n",
      "  File \"c:\\Users\\virtue\\anaconda3\\envs\\study\\lib\\site-packages\\telegram\\bot.py\", line 3057, in get_updates\n",
      "    self._post(\n",
      "  File \"c:\\Users\\virtue\\anaconda3\\envs\\study\\lib\\site-packages\\telegram\\bot.py\", line 298, in _post\n",
      "    return self.request.post(\n",
      "  File \"c:\\Users\\virtue\\anaconda3\\envs\\study\\lib\\site-packages\\telegram\\utils\\request.py\", line 361, in post\n",
      "    result = self._request_wrapper(\n",
      "  File \"c:\\Users\\virtue\\anaconda3\\envs\\study\\lib\\site-packages\\telegram\\utils\\request.py\", line 283, in _request_wrapper\n",
      "    raise Conflict(message)\n",
      "telegram.error.Conflict: Conflict: terminated by other getUpdates request; make sure that only one bot instance is running\n",
      "Error while getting Updates: Conflict: terminated by other getUpdates request; make sure that only one bot instance is running\n",
      "No error handlers are registered, logging exception.\n",
      "Traceback (most recent call last):\n",
      "  File \"c:\\Users\\virtue\\anaconda3\\envs\\study\\lib\\site-packages\\telegram\\ext\\updater.py\", line 651, in _network_loop_retry\n",
      "    if not action_cb():\n",
      "  File \"c:\\Users\\virtue\\anaconda3\\envs\\study\\lib\\site-packages\\telegram\\ext\\updater.py\", line 602, in polling_action_cb\n",
      "    updates = self.bot.get_updates(\n",
      "  File \"c:\\Users\\virtue\\anaconda3\\envs\\study\\lib\\site-packages\\telegram\\ext\\extbot.py\", line 226, in get_updates\n",
      "    updates = super().get_updates(\n",
      "  File \"c:\\Users\\virtue\\anaconda3\\envs\\study\\lib\\site-packages\\telegram\\bot.py\", line 133, in decorator\n",
      "    result = func(*args, **kwargs)\n",
      "  File \"c:\\Users\\virtue\\anaconda3\\envs\\study\\lib\\site-packages\\telegram\\bot.py\", line 3057, in get_updates\n",
      "    self._post(\n",
      "  File \"c:\\Users\\virtue\\anaconda3\\envs\\study\\lib\\site-packages\\telegram\\bot.py\", line 298, in _post\n",
      "    return self.request.post(\n",
      "  File \"c:\\Users\\virtue\\anaconda3\\envs\\study\\lib\\site-packages\\telegram\\utils\\request.py\", line 361, in post\n",
      "    result = self._request_wrapper(\n",
      "  File \"c:\\Users\\virtue\\anaconda3\\envs\\study\\lib\\site-packages\\telegram\\utils\\request.py\", line 283, in _request_wrapper\n",
      "    raise Conflict(message)\n",
      "telegram.error.Conflict: Conflict: terminated by other getUpdates request; make sure that only one bot instance is running\n",
      "Error while getting Updates: Conflict: terminated by other getUpdates request; make sure that only one bot instance is running\n",
      "No error handlers are registered, logging exception.\n",
      "Traceback (most recent call last):\n",
      "  File \"c:\\Users\\virtue\\anaconda3\\envs\\study\\lib\\site-packages\\telegram\\ext\\updater.py\", line 651, in _network_loop_retry\n",
      "    if not action_cb():\n",
      "  File \"c:\\Users\\virtue\\anaconda3\\envs\\study\\lib\\site-packages\\telegram\\ext\\updater.py\", line 602, in polling_action_cb\n",
      "    updates = self.bot.get_updates(\n",
      "  File \"c:\\Users\\virtue\\anaconda3\\envs\\study\\lib\\site-packages\\telegram\\ext\\extbot.py\", line 226, in get_updates\n",
      "    updates = super().get_updates(\n",
      "  File \"c:\\Users\\virtue\\anaconda3\\envs\\study\\lib\\site-packages\\telegram\\bot.py\", line 133, in decorator\n",
      "    result = func(*args, **kwargs)\n",
      "  File \"c:\\Users\\virtue\\anaconda3\\envs\\study\\lib\\site-packages\\telegram\\bot.py\", line 3057, in get_updates\n",
      "    self._post(\n",
      "  File \"c:\\Users\\virtue\\anaconda3\\envs\\study\\lib\\site-packages\\telegram\\bot.py\", line 298, in _post\n",
      "    return self.request.post(\n",
      "  File \"c:\\Users\\virtue\\anaconda3\\envs\\study\\lib\\site-packages\\telegram\\utils\\request.py\", line 361, in post\n",
      "    result = self._request_wrapper(\n",
      "  File \"c:\\Users\\virtue\\anaconda3\\envs\\study\\lib\\site-packages\\telegram\\utils\\request.py\", line 283, in _request_wrapper\n",
      "    raise Conflict(message)\n",
      "telegram.error.Conflict: Conflict: terminated by other getUpdates request; make sure that only one bot instance is running\n",
      "Error while getting Updates: Conflict: terminated by other getUpdates request; make sure that only one bot instance is running\n",
      "No error handlers are registered, logging exception.\n",
      "Traceback (most recent call last):\n",
      "  File \"c:\\Users\\virtue\\anaconda3\\envs\\study\\lib\\site-packages\\telegram\\ext\\updater.py\", line 651, in _network_loop_retry\n",
      "    if not action_cb():\n",
      "  File \"c:\\Users\\virtue\\anaconda3\\envs\\study\\lib\\site-packages\\telegram\\ext\\updater.py\", line 602, in polling_action_cb\n",
      "    updates = self.bot.get_updates(\n",
      "  File \"c:\\Users\\virtue\\anaconda3\\envs\\study\\lib\\site-packages\\telegram\\ext\\extbot.py\", line 226, in get_updates\n",
      "    updates = super().get_updates(\n",
      "  File \"c:\\Users\\virtue\\anaconda3\\envs\\study\\lib\\site-packages\\telegram\\bot.py\", line 133, in decorator\n",
      "    result = func(*args, **kwargs)\n",
      "  File \"c:\\Users\\virtue\\anaconda3\\envs\\study\\lib\\site-packages\\telegram\\bot.py\", line 3057, in get_updates\n",
      "    self._post(\n",
      "  File \"c:\\Users\\virtue\\anaconda3\\envs\\study\\lib\\site-packages\\telegram\\bot.py\", line 298, in _post\n",
      "    return self.request.post(\n",
      "  File \"c:\\Users\\virtue\\anaconda3\\envs\\study\\lib\\site-packages\\telegram\\utils\\request.py\", line 361, in post\n",
      "    result = self._request_wrapper(\n",
      "  File \"c:\\Users\\virtue\\anaconda3\\envs\\study\\lib\\site-packages\\telegram\\utils\\request.py\", line 283, in _request_wrapper\n",
      "    raise Conflict(message)\n",
      "telegram.error.Conflict: Conflict: terminated by other getUpdates request; make sure that only one bot instance is running\n",
      "Error while getting Updates: Conflict: terminated by other getUpdates request; make sure that only one bot instance is running\n",
      "No error handlers are registered, logging exception.\n",
      "Traceback (most recent call last):\n",
      "  File \"c:\\Users\\virtue\\anaconda3\\envs\\study\\lib\\site-packages\\telegram\\ext\\updater.py\", line 651, in _network_loop_retry\n",
      "    if not action_cb():\n",
      "  File \"c:\\Users\\virtue\\anaconda3\\envs\\study\\lib\\site-packages\\telegram\\ext\\updater.py\", line 602, in polling_action_cb\n",
      "    updates = self.bot.get_updates(\n",
      "  File \"c:\\Users\\virtue\\anaconda3\\envs\\study\\lib\\site-packages\\telegram\\ext\\extbot.py\", line 226, in get_updates\n",
      "    updates = super().get_updates(\n",
      "  File \"c:\\Users\\virtue\\anaconda3\\envs\\study\\lib\\site-packages\\telegram\\bot.py\", line 133, in decorator\n",
      "    result = func(*args, **kwargs)\n",
      "  File \"c:\\Users\\virtue\\anaconda3\\envs\\study\\lib\\site-packages\\telegram\\bot.py\", line 3057, in get_updates\n",
      "    self._post(\n",
      "  File \"c:\\Users\\virtue\\anaconda3\\envs\\study\\lib\\site-packages\\telegram\\bot.py\", line 298, in _post\n",
      "    return self.request.post(\n",
      "  File \"c:\\Users\\virtue\\anaconda3\\envs\\study\\lib\\site-packages\\telegram\\utils\\request.py\", line 361, in post\n",
      "    result = self._request_wrapper(\n",
      "  File \"c:\\Users\\virtue\\anaconda3\\envs\\study\\lib\\site-packages\\telegram\\utils\\request.py\", line 283, in _request_wrapper\n",
      "    raise Conflict(message)\n",
      "telegram.error.Conflict: Conflict: terminated by other getUpdates request; make sure that only one bot instance is running\n",
      "Error while getting Updates: Conflict: terminated by other getUpdates request; make sure that only one bot instance is running\n",
      "No error handlers are registered, logging exception.\n",
      "Traceback (most recent call last):\n",
      "  File \"c:\\Users\\virtue\\anaconda3\\envs\\study\\lib\\site-packages\\telegram\\ext\\updater.py\", line 651, in _network_loop_retry\n",
      "    if not action_cb():\n",
      "  File \"c:\\Users\\virtue\\anaconda3\\envs\\study\\lib\\site-packages\\telegram\\ext\\updater.py\", line 602, in polling_action_cb\n",
      "    updates = self.bot.get_updates(\n",
      "  File \"c:\\Users\\virtue\\anaconda3\\envs\\study\\lib\\site-packages\\telegram\\ext\\extbot.py\", line 226, in get_updates\n",
      "    updates = super().get_updates(\n",
      "  File \"c:\\Users\\virtue\\anaconda3\\envs\\study\\lib\\site-packages\\telegram\\bot.py\", line 133, in decorator\n",
      "    result = func(*args, **kwargs)\n",
      "  File \"c:\\Users\\virtue\\anaconda3\\envs\\study\\lib\\site-packages\\telegram\\bot.py\", line 3057, in get_updates\n",
      "    self._post(\n",
      "  File \"c:\\Users\\virtue\\anaconda3\\envs\\study\\lib\\site-packages\\telegram\\bot.py\", line 298, in _post\n",
      "    return self.request.post(\n",
      "  File \"c:\\Users\\virtue\\anaconda3\\envs\\study\\lib\\site-packages\\telegram\\utils\\request.py\", line 361, in post\n",
      "    result = self._request_wrapper(\n",
      "  File \"c:\\Users\\virtue\\anaconda3\\envs\\study\\lib\\site-packages\\telegram\\utils\\request.py\", line 283, in _request_wrapper\n",
      "    raise Conflict(message)\n",
      "telegram.error.Conflict: Conflict: terminated by other getUpdates request; make sure that only one bot instance is running\n",
      "Error while getting Updates: Conflict: terminated by other getUpdates request; make sure that only one bot instance is running\n",
      "No error handlers are registered, logging exception.\n",
      "Traceback (most recent call last):\n",
      "  File \"c:\\Users\\virtue\\anaconda3\\envs\\study\\lib\\site-packages\\telegram\\ext\\updater.py\", line 651, in _network_loop_retry\n",
      "    if not action_cb():\n",
      "  File \"c:\\Users\\virtue\\anaconda3\\envs\\study\\lib\\site-packages\\telegram\\ext\\updater.py\", line 602, in polling_action_cb\n",
      "    updates = self.bot.get_updates(\n",
      "  File \"c:\\Users\\virtue\\anaconda3\\envs\\study\\lib\\site-packages\\telegram\\ext\\extbot.py\", line 226, in get_updates\n",
      "    updates = super().get_updates(\n",
      "  File \"c:\\Users\\virtue\\anaconda3\\envs\\study\\lib\\site-packages\\telegram\\bot.py\", line 133, in decorator\n",
      "    result = func(*args, **kwargs)\n",
      "  File \"c:\\Users\\virtue\\anaconda3\\envs\\study\\lib\\site-packages\\telegram\\bot.py\", line 3057, in get_updates\n",
      "    self._post(\n",
      "  File \"c:\\Users\\virtue\\anaconda3\\envs\\study\\lib\\site-packages\\telegram\\bot.py\", line 298, in _post\n",
      "    return self.request.post(\n",
      "  File \"c:\\Users\\virtue\\anaconda3\\envs\\study\\lib\\site-packages\\telegram\\utils\\request.py\", line 361, in post\n",
      "    result = self._request_wrapper(\n",
      "  File \"c:\\Users\\virtue\\anaconda3\\envs\\study\\lib\\site-packages\\telegram\\utils\\request.py\", line 283, in _request_wrapper\n",
      "    raise Conflict(message)\n",
      "telegram.error.Conflict: Conflict: terminated by other getUpdates request; make sure that only one bot instance is running\n",
      "Error while getting Updates: Conflict: terminated by other getUpdates request; make sure that only one bot instance is running\n",
      "No error handlers are registered, logging exception.\n",
      "Traceback (most recent call last):\n",
      "  File \"c:\\Users\\virtue\\anaconda3\\envs\\study\\lib\\site-packages\\telegram\\ext\\updater.py\", line 651, in _network_loop_retry\n",
      "    if not action_cb():\n",
      "  File \"c:\\Users\\virtue\\anaconda3\\envs\\study\\lib\\site-packages\\telegram\\ext\\updater.py\", line 602, in polling_action_cb\n",
      "    updates = self.bot.get_updates(\n",
      "  File \"c:\\Users\\virtue\\anaconda3\\envs\\study\\lib\\site-packages\\telegram\\ext\\extbot.py\", line 226, in get_updates\n",
      "    updates = super().get_updates(\n",
      "  File \"c:\\Users\\virtue\\anaconda3\\envs\\study\\lib\\site-packages\\telegram\\bot.py\", line 133, in decorator\n",
      "    result = func(*args, **kwargs)\n",
      "  File \"c:\\Users\\virtue\\anaconda3\\envs\\study\\lib\\site-packages\\telegram\\bot.py\", line 3057, in get_updates\n",
      "    self._post(\n",
      "  File \"c:\\Users\\virtue\\anaconda3\\envs\\study\\lib\\site-packages\\telegram\\bot.py\", line 298, in _post\n",
      "    return self.request.post(\n",
      "  File \"c:\\Users\\virtue\\anaconda3\\envs\\study\\lib\\site-packages\\telegram\\utils\\request.py\", line 361, in post\n",
      "    result = self._request_wrapper(\n",
      "  File \"c:\\Users\\virtue\\anaconda3\\envs\\study\\lib\\site-packages\\telegram\\utils\\request.py\", line 283, in _request_wrapper\n",
      "    raise Conflict(message)\n",
      "telegram.error.Conflict: Conflict: terminated by other getUpdates request; make sure that only one bot instance is running\n",
      "Error while getting Updates: Conflict: terminated by other getUpdates request; make sure that only one bot instance is running\n",
      "No error handlers are registered, logging exception.\n",
      "Traceback (most recent call last):\n",
      "  File \"c:\\Users\\virtue\\anaconda3\\envs\\study\\lib\\site-packages\\telegram\\ext\\updater.py\", line 651, in _network_loop_retry\n",
      "    if not action_cb():\n",
      "  File \"c:\\Users\\virtue\\anaconda3\\envs\\study\\lib\\site-packages\\telegram\\ext\\updater.py\", line 602, in polling_action_cb\n",
      "    updates = self.bot.get_updates(\n",
      "  File \"c:\\Users\\virtue\\anaconda3\\envs\\study\\lib\\site-packages\\telegram\\ext\\extbot.py\", line 226, in get_updates\n",
      "    updates = super().get_updates(\n",
      "  File \"c:\\Users\\virtue\\anaconda3\\envs\\study\\lib\\site-packages\\telegram\\bot.py\", line 133, in decorator\n",
      "    result = func(*args, **kwargs)\n",
      "  File \"c:\\Users\\virtue\\anaconda3\\envs\\study\\lib\\site-packages\\telegram\\bot.py\", line 3057, in get_updates\n",
      "    self._post(\n",
      "  File \"c:\\Users\\virtue\\anaconda3\\envs\\study\\lib\\site-packages\\telegram\\bot.py\", line 298, in _post\n",
      "    return self.request.post(\n",
      "  File \"c:\\Users\\virtue\\anaconda3\\envs\\study\\lib\\site-packages\\telegram\\utils\\request.py\", line 361, in post\n",
      "    result = self._request_wrapper(\n",
      "  File \"c:\\Users\\virtue\\anaconda3\\envs\\study\\lib\\site-packages\\telegram\\utils\\request.py\", line 283, in _request_wrapper\n",
      "    raise Conflict(message)\n",
      "telegram.error.Conflict: Conflict: terminated by other getUpdates request; make sure that only one bot instance is running\n",
      "Error while getting Updates: Conflict: terminated by other getUpdates request; make sure that only one bot instance is running\n",
      "No error handlers are registered, logging exception.\n",
      "Traceback (most recent call last):\n",
      "  File \"c:\\Users\\virtue\\anaconda3\\envs\\study\\lib\\site-packages\\telegram\\ext\\updater.py\", line 651, in _network_loop_retry\n",
      "    if not action_cb():\n",
      "  File \"c:\\Users\\virtue\\anaconda3\\envs\\study\\lib\\site-packages\\telegram\\ext\\updater.py\", line 602, in polling_action_cb\n",
      "    updates = self.bot.get_updates(\n",
      "  File \"c:\\Users\\virtue\\anaconda3\\envs\\study\\lib\\site-packages\\telegram\\ext\\extbot.py\", line 226, in get_updates\n",
      "    updates = super().get_updates(\n",
      "  File \"c:\\Users\\virtue\\anaconda3\\envs\\study\\lib\\site-packages\\telegram\\bot.py\", line 133, in decorator\n",
      "    result = func(*args, **kwargs)\n",
      "  File \"c:\\Users\\virtue\\anaconda3\\envs\\study\\lib\\site-packages\\telegram\\bot.py\", line 3057, in get_updates\n",
      "    self._post(\n",
      "  File \"c:\\Users\\virtue\\anaconda3\\envs\\study\\lib\\site-packages\\telegram\\bot.py\", line 298, in _post\n",
      "    return self.request.post(\n",
      "  File \"c:\\Users\\virtue\\anaconda3\\envs\\study\\lib\\site-packages\\telegram\\utils\\request.py\", line 361, in post\n",
      "    result = self._request_wrapper(\n",
      "  File \"c:\\Users\\virtue\\anaconda3\\envs\\study\\lib\\site-packages\\telegram\\utils\\request.py\", line 283, in _request_wrapper\n",
      "    raise Conflict(message)\n",
      "telegram.error.Conflict: Conflict: terminated by other getUpdates request; make sure that only one bot instance is running\n",
      "Error while getting Updates: Conflict: terminated by other getUpdates request; make sure that only one bot instance is running\n",
      "No error handlers are registered, logging exception.\n",
      "Traceback (most recent call last):\n",
      "  File \"c:\\Users\\virtue\\anaconda3\\envs\\study\\lib\\site-packages\\telegram\\ext\\updater.py\", line 651, in _network_loop_retry\n",
      "    if not action_cb():\n",
      "  File \"c:\\Users\\virtue\\anaconda3\\envs\\study\\lib\\site-packages\\telegram\\ext\\updater.py\", line 602, in polling_action_cb\n",
      "    updates = self.bot.get_updates(\n",
      "  File \"c:\\Users\\virtue\\anaconda3\\envs\\study\\lib\\site-packages\\telegram\\ext\\extbot.py\", line 226, in get_updates\n",
      "    updates = super().get_updates(\n",
      "  File \"c:\\Users\\virtue\\anaconda3\\envs\\study\\lib\\site-packages\\telegram\\bot.py\", line 133, in decorator\n",
      "    result = func(*args, **kwargs)\n",
      "  File \"c:\\Users\\virtue\\anaconda3\\envs\\study\\lib\\site-packages\\telegram\\bot.py\", line 3057, in get_updates\n",
      "    self._post(\n",
      "  File \"c:\\Users\\virtue\\anaconda3\\envs\\study\\lib\\site-packages\\telegram\\bot.py\", line 298, in _post\n",
      "    return self.request.post(\n",
      "  File \"c:\\Users\\virtue\\anaconda3\\envs\\study\\lib\\site-packages\\telegram\\utils\\request.py\", line 361, in post\n",
      "    result = self._request_wrapper(\n",
      "  File \"c:\\Users\\virtue\\anaconda3\\envs\\study\\lib\\site-packages\\telegram\\utils\\request.py\", line 283, in _request_wrapper\n",
      "    raise Conflict(message)\n",
      "telegram.error.Conflict: Conflict: terminated by other getUpdates request; make sure that only one bot instance is running\n",
      "Error while getting Updates: Conflict: terminated by other getUpdates request; make sure that only one bot instance is running\n",
      "No error handlers are registered, logging exception.\n",
      "Traceback (most recent call last):\n",
      "  File \"c:\\Users\\virtue\\anaconda3\\envs\\study\\lib\\site-packages\\telegram\\ext\\updater.py\", line 651, in _network_loop_retry\n",
      "    if not action_cb():\n",
      "  File \"c:\\Users\\virtue\\anaconda3\\envs\\study\\lib\\site-packages\\telegram\\ext\\updater.py\", line 602, in polling_action_cb\n",
      "    updates = self.bot.get_updates(\n",
      "  File \"c:\\Users\\virtue\\anaconda3\\envs\\study\\lib\\site-packages\\telegram\\ext\\extbot.py\", line 226, in get_updates\n",
      "    updates = super().get_updates(\n",
      "  File \"c:\\Users\\virtue\\anaconda3\\envs\\study\\lib\\site-packages\\telegram\\bot.py\", line 133, in decorator\n",
      "    result = func(*args, **kwargs)\n",
      "  File \"c:\\Users\\virtue\\anaconda3\\envs\\study\\lib\\site-packages\\telegram\\bot.py\", line 3057, in get_updates\n",
      "    self._post(\n",
      "  File \"c:\\Users\\virtue\\anaconda3\\envs\\study\\lib\\site-packages\\telegram\\bot.py\", line 298, in _post\n",
      "    return self.request.post(\n",
      "  File \"c:\\Users\\virtue\\anaconda3\\envs\\study\\lib\\site-packages\\telegram\\utils\\request.py\", line 361, in post\n",
      "    result = self._request_wrapper(\n",
      "  File \"c:\\Users\\virtue\\anaconda3\\envs\\study\\lib\\site-packages\\telegram\\utils\\request.py\", line 283, in _request_wrapper\n",
      "    raise Conflict(message)\n",
      "telegram.error.Conflict: Conflict: terminated by other getUpdates request; make sure that only one bot instance is running\n",
      "Error while getting Updates: Conflict: terminated by other getUpdates request; make sure that only one bot instance is running\n",
      "No error handlers are registered, logging exception.\n",
      "Traceback (most recent call last):\n",
      "  File \"c:\\Users\\virtue\\anaconda3\\envs\\study\\lib\\site-packages\\telegram\\ext\\updater.py\", line 651, in _network_loop_retry\n",
      "    if not action_cb():\n",
      "  File \"c:\\Users\\virtue\\anaconda3\\envs\\study\\lib\\site-packages\\telegram\\ext\\updater.py\", line 602, in polling_action_cb\n",
      "    updates = self.bot.get_updates(\n",
      "  File \"c:\\Users\\virtue\\anaconda3\\envs\\study\\lib\\site-packages\\telegram\\ext\\extbot.py\", line 226, in get_updates\n",
      "    updates = super().get_updates(\n",
      "  File \"c:\\Users\\virtue\\anaconda3\\envs\\study\\lib\\site-packages\\telegram\\bot.py\", line 133, in decorator\n",
      "    result = func(*args, **kwargs)\n",
      "  File \"c:\\Users\\virtue\\anaconda3\\envs\\study\\lib\\site-packages\\telegram\\bot.py\", line 3057, in get_updates\n",
      "    self._post(\n",
      "  File \"c:\\Users\\virtue\\anaconda3\\envs\\study\\lib\\site-packages\\telegram\\bot.py\", line 298, in _post\n",
      "    return self.request.post(\n",
      "  File \"c:\\Users\\virtue\\anaconda3\\envs\\study\\lib\\site-packages\\telegram\\utils\\request.py\", line 361, in post\n",
      "    result = self._request_wrapper(\n",
      "  File \"c:\\Users\\virtue\\anaconda3\\envs\\study\\lib\\site-packages\\telegram\\utils\\request.py\", line 283, in _request_wrapper\n",
      "    raise Conflict(message)\n",
      "telegram.error.Conflict: Conflict: terminated by other getUpdates request; make sure that only one bot instance is running\n",
      "Error while getting Updates: Conflict: terminated by other getUpdates request; make sure that only one bot instance is running\n",
      "No error handlers are registered, logging exception.\n",
      "Traceback (most recent call last):\n",
      "  File \"c:\\Users\\virtue\\anaconda3\\envs\\study\\lib\\site-packages\\telegram\\ext\\updater.py\", line 651, in _network_loop_retry\n",
      "    if not action_cb():\n",
      "  File \"c:\\Users\\virtue\\anaconda3\\envs\\study\\lib\\site-packages\\telegram\\ext\\updater.py\", line 602, in polling_action_cb\n",
      "    updates = self.bot.get_updates(\n",
      "  File \"c:\\Users\\virtue\\anaconda3\\envs\\study\\lib\\site-packages\\telegram\\ext\\extbot.py\", line 226, in get_updates\n",
      "    updates = super().get_updates(\n",
      "  File \"c:\\Users\\virtue\\anaconda3\\envs\\study\\lib\\site-packages\\telegram\\bot.py\", line 133, in decorator\n",
      "    result = func(*args, **kwargs)\n",
      "  File \"c:\\Users\\virtue\\anaconda3\\envs\\study\\lib\\site-packages\\telegram\\bot.py\", line 3057, in get_updates\n",
      "    self._post(\n",
      "  File \"c:\\Users\\virtue\\anaconda3\\envs\\study\\lib\\site-packages\\telegram\\bot.py\", line 298, in _post\n",
      "    return self.request.post(\n",
      "  File \"c:\\Users\\virtue\\anaconda3\\envs\\study\\lib\\site-packages\\telegram\\utils\\request.py\", line 361, in post\n",
      "    result = self._request_wrapper(\n",
      "  File \"c:\\Users\\virtue\\anaconda3\\envs\\study\\lib\\site-packages\\telegram\\utils\\request.py\", line 283, in _request_wrapper\n",
      "    raise Conflict(message)\n",
      "telegram.error.Conflict: Conflict: terminated by other getUpdates request; make sure that only one bot instance is running\n",
      "Error while getting Updates: Conflict: terminated by other getUpdates request; make sure that only one bot instance is running\n",
      "No error handlers are registered, logging exception.\n",
      "Traceback (most recent call last):\n",
      "  File \"c:\\Users\\virtue\\anaconda3\\envs\\study\\lib\\site-packages\\telegram\\ext\\updater.py\", line 651, in _network_loop_retry\n",
      "    if not action_cb():\n",
      "  File \"c:\\Users\\virtue\\anaconda3\\envs\\study\\lib\\site-packages\\telegram\\ext\\updater.py\", line 602, in polling_action_cb\n",
      "    updates = self.bot.get_updates(\n",
      "  File \"c:\\Users\\virtue\\anaconda3\\envs\\study\\lib\\site-packages\\telegram\\ext\\extbot.py\", line 226, in get_updates\n",
      "    updates = super().get_updates(\n",
      "  File \"c:\\Users\\virtue\\anaconda3\\envs\\study\\lib\\site-packages\\telegram\\bot.py\", line 133, in decorator\n",
      "    result = func(*args, **kwargs)\n",
      "  File \"c:\\Users\\virtue\\anaconda3\\envs\\study\\lib\\site-packages\\telegram\\bot.py\", line 3057, in get_updates\n",
      "    self._post(\n",
      "  File \"c:\\Users\\virtue\\anaconda3\\envs\\study\\lib\\site-packages\\telegram\\bot.py\", line 298, in _post\n",
      "    return self.request.post(\n",
      "  File \"c:\\Users\\virtue\\anaconda3\\envs\\study\\lib\\site-packages\\telegram\\utils\\request.py\", line 361, in post\n",
      "    result = self._request_wrapper(\n",
      "  File \"c:\\Users\\virtue\\anaconda3\\envs\\study\\lib\\site-packages\\telegram\\utils\\request.py\", line 283, in _request_wrapper\n",
      "    raise Conflict(message)\n",
      "telegram.error.Conflict: Conflict: terminated by other getUpdates request; make sure that only one bot instance is running\n",
      "Error while getting Updates: Conflict: terminated by other getUpdates request; make sure that only one bot instance is running\n",
      "No error handlers are registered, logging exception.\n",
      "Traceback (most recent call last):\n",
      "  File \"c:\\Users\\virtue\\anaconda3\\envs\\study\\lib\\site-packages\\telegram\\ext\\updater.py\", line 651, in _network_loop_retry\n",
      "    if not action_cb():\n",
      "  File \"c:\\Users\\virtue\\anaconda3\\envs\\study\\lib\\site-packages\\telegram\\ext\\updater.py\", line 602, in polling_action_cb\n",
      "    updates = self.bot.get_updates(\n",
      "  File \"c:\\Users\\virtue\\anaconda3\\envs\\study\\lib\\site-packages\\telegram\\ext\\extbot.py\", line 226, in get_updates\n",
      "    updates = super().get_updates(\n",
      "  File \"c:\\Users\\virtue\\anaconda3\\envs\\study\\lib\\site-packages\\telegram\\bot.py\", line 133, in decorator\n",
      "    result = func(*args, **kwargs)\n",
      "  File \"c:\\Users\\virtue\\anaconda3\\envs\\study\\lib\\site-packages\\telegram\\bot.py\", line 3057, in get_updates\n",
      "    self._post(\n",
      "  File \"c:\\Users\\virtue\\anaconda3\\envs\\study\\lib\\site-packages\\telegram\\bot.py\", line 298, in _post\n",
      "    return self.request.post(\n",
      "  File \"c:\\Users\\virtue\\anaconda3\\envs\\study\\lib\\site-packages\\telegram\\utils\\request.py\", line 361, in post\n",
      "    result = self._request_wrapper(\n",
      "  File \"c:\\Users\\virtue\\anaconda3\\envs\\study\\lib\\site-packages\\telegram\\utils\\request.py\", line 283, in _request_wrapper\n",
      "    raise Conflict(message)\n",
      "telegram.error.Conflict: Conflict: terminated by other getUpdates request; make sure that only one bot instance is running\n",
      "Error while getting Updates: Conflict: terminated by other getUpdates request; make sure that only one bot instance is running\n",
      "No error handlers are registered, logging exception.\n",
      "Traceback (most recent call last):\n",
      "  File \"c:\\Users\\virtue\\anaconda3\\envs\\study\\lib\\site-packages\\telegram\\ext\\updater.py\", line 651, in _network_loop_retry\n",
      "    if not action_cb():\n",
      "  File \"c:\\Users\\virtue\\anaconda3\\envs\\study\\lib\\site-packages\\telegram\\ext\\updater.py\", line 602, in polling_action_cb\n",
      "    updates = self.bot.get_updates(\n",
      "  File \"c:\\Users\\virtue\\anaconda3\\envs\\study\\lib\\site-packages\\telegram\\ext\\extbot.py\", line 226, in get_updates\n",
      "    updates = super().get_updates(\n",
      "  File \"c:\\Users\\virtue\\anaconda3\\envs\\study\\lib\\site-packages\\telegram\\bot.py\", line 133, in decorator\n",
      "    result = func(*args, **kwargs)\n",
      "  File \"c:\\Users\\virtue\\anaconda3\\envs\\study\\lib\\site-packages\\telegram\\bot.py\", line 3057, in get_updates\n",
      "    self._post(\n",
      "  File \"c:\\Users\\virtue\\anaconda3\\envs\\study\\lib\\site-packages\\telegram\\bot.py\", line 298, in _post\n",
      "    return self.request.post(\n",
      "  File \"c:\\Users\\virtue\\anaconda3\\envs\\study\\lib\\site-packages\\telegram\\utils\\request.py\", line 361, in post\n",
      "    result = self._request_wrapper(\n",
      "  File \"c:\\Users\\virtue\\anaconda3\\envs\\study\\lib\\site-packages\\telegram\\utils\\request.py\", line 283, in _request_wrapper\n",
      "    raise Conflict(message)\n",
      "telegram.error.Conflict: Conflict: terminated by other getUpdates request; make sure that only one bot instance is running\n",
      "Error while getting Updates: Conflict: terminated by other getUpdates request; make sure that only one bot instance is running\n",
      "No error handlers are registered, logging exception.\n",
      "Traceback (most recent call last):\n",
      "  File \"c:\\Users\\virtue\\anaconda3\\envs\\study\\lib\\site-packages\\telegram\\ext\\updater.py\", line 651, in _network_loop_retry\n",
      "    if not action_cb():\n",
      "  File \"c:\\Users\\virtue\\anaconda3\\envs\\study\\lib\\site-packages\\telegram\\ext\\updater.py\", line 602, in polling_action_cb\n",
      "    updates = self.bot.get_updates(\n",
      "  File \"c:\\Users\\virtue\\anaconda3\\envs\\study\\lib\\site-packages\\telegram\\ext\\extbot.py\", line 226, in get_updates\n",
      "    updates = super().get_updates(\n",
      "  File \"c:\\Users\\virtue\\anaconda3\\envs\\study\\lib\\site-packages\\telegram\\bot.py\", line 133, in decorator\n",
      "    result = func(*args, **kwargs)\n",
      "  File \"c:\\Users\\virtue\\anaconda3\\envs\\study\\lib\\site-packages\\telegram\\bot.py\", line 3057, in get_updates\n",
      "    self._post(\n",
      "  File \"c:\\Users\\virtue\\anaconda3\\envs\\study\\lib\\site-packages\\telegram\\bot.py\", line 298, in _post\n",
      "    return self.request.post(\n",
      "  File \"c:\\Users\\virtue\\anaconda3\\envs\\study\\lib\\site-packages\\telegram\\utils\\request.py\", line 361, in post\n",
      "    result = self._request_wrapper(\n",
      "  File \"c:\\Users\\virtue\\anaconda3\\envs\\study\\lib\\site-packages\\telegram\\utils\\request.py\", line 283, in _request_wrapper\n",
      "    raise Conflict(message)\n",
      "telegram.error.Conflict: Conflict: terminated by other getUpdates request; make sure that only one bot instance is running\n",
      "Error while getting Updates: Conflict: terminated by other getUpdates request; make sure that only one bot instance is running\n",
      "No error handlers are registered, logging exception.\n",
      "Traceback (most recent call last):\n",
      "  File \"c:\\Users\\virtue\\anaconda3\\envs\\study\\lib\\site-packages\\telegram\\ext\\updater.py\", line 651, in _network_loop_retry\n",
      "    if not action_cb():\n",
      "  File \"c:\\Users\\virtue\\anaconda3\\envs\\study\\lib\\site-packages\\telegram\\ext\\updater.py\", line 602, in polling_action_cb\n",
      "    updates = self.bot.get_updates(\n",
      "  File \"c:\\Users\\virtue\\anaconda3\\envs\\study\\lib\\site-packages\\telegram\\ext\\extbot.py\", line 226, in get_updates\n",
      "    updates = super().get_updates(\n",
      "  File \"c:\\Users\\virtue\\anaconda3\\envs\\study\\lib\\site-packages\\telegram\\bot.py\", line 133, in decorator\n",
      "    result = func(*args, **kwargs)\n",
      "  File \"c:\\Users\\virtue\\anaconda3\\envs\\study\\lib\\site-packages\\telegram\\bot.py\", line 3057, in get_updates\n",
      "    self._post(\n",
      "  File \"c:\\Users\\virtue\\anaconda3\\envs\\study\\lib\\site-packages\\telegram\\bot.py\", line 298, in _post\n",
      "    return self.request.post(\n",
      "  File \"c:\\Users\\virtue\\anaconda3\\envs\\study\\lib\\site-packages\\telegram\\utils\\request.py\", line 361, in post\n",
      "    result = self._request_wrapper(\n",
      "  File \"c:\\Users\\virtue\\anaconda3\\envs\\study\\lib\\site-packages\\telegram\\utils\\request.py\", line 283, in _request_wrapper\n",
      "    raise Conflict(message)\n",
      "telegram.error.Conflict: Conflict: terminated by other getUpdates request; make sure that only one bot instance is running\n",
      "Error while getting Updates: Conflict: terminated by other getUpdates request; make sure that only one bot instance is running\n",
      "No error handlers are registered, logging exception.\n",
      "Traceback (most recent call last):\n",
      "  File \"c:\\Users\\virtue\\anaconda3\\envs\\study\\lib\\site-packages\\telegram\\ext\\updater.py\", line 651, in _network_loop_retry\n",
      "    if not action_cb():\n",
      "  File \"c:\\Users\\virtue\\anaconda3\\envs\\study\\lib\\site-packages\\telegram\\ext\\updater.py\", line 602, in polling_action_cb\n",
      "    updates = self.bot.get_updates(\n",
      "  File \"c:\\Users\\virtue\\anaconda3\\envs\\study\\lib\\site-packages\\telegram\\ext\\extbot.py\", line 226, in get_updates\n",
      "    updates = super().get_updates(\n",
      "  File \"c:\\Users\\virtue\\anaconda3\\envs\\study\\lib\\site-packages\\telegram\\bot.py\", line 133, in decorator\n",
      "    result = func(*args, **kwargs)\n",
      "  File \"c:\\Users\\virtue\\anaconda3\\envs\\study\\lib\\site-packages\\telegram\\bot.py\", line 3057, in get_updates\n",
      "    self._post(\n",
      "  File \"c:\\Users\\virtue\\anaconda3\\envs\\study\\lib\\site-packages\\telegram\\bot.py\", line 298, in _post\n",
      "    return self.request.post(\n",
      "  File \"c:\\Users\\virtue\\anaconda3\\envs\\study\\lib\\site-packages\\telegram\\utils\\request.py\", line 361, in post\n",
      "    result = self._request_wrapper(\n",
      "  File \"c:\\Users\\virtue\\anaconda3\\envs\\study\\lib\\site-packages\\telegram\\utils\\request.py\", line 283, in _request_wrapper\n",
      "    raise Conflict(message)\n",
      "telegram.error.Conflict: Conflict: terminated by other getUpdates request; make sure that only one bot instance is running\n",
      "No error handlers are registered, logging exception.\n",
      "Traceback (most recent call last):\n",
      "  File \"c:\\Users\\virtue\\anaconda3\\envs\\study\\lib\\site-packages\\telegram\\ext\\dispatcher.py\", line 557, in process_update\n",
      "    handler.handle_update(update, self, check, context)\n",
      "  File \"c:\\Users\\virtue\\anaconda3\\envs\\study\\lib\\site-packages\\telegram\\ext\\handler.py\", line 199, in handle_update\n",
      "    return self.callback(update, context)\n",
      "  File \"C:\\Users\\virtue\\AppData\\Local\\Temp\\ipykernel_16040\\3014515975.py\", line 26, in handler\n",
      "    data = naver_crawling()\n",
      "  File \"C:\\Users\\virtue\\AppData\\Local\\Temp\\ipykernel_16040\\3681364787.py\", line 38, in naver_crawling\n",
      "    final_result='원어명: '+ spain_result['원어명'] + '위치: '+ spain_result['위치']+ '시간대: '+spain_result['시간대'] +'면적(㎢): '+ spain_result['면적(㎢)']+'시간대: '+spain_result['시간대']+'수도: '+spain_result['수도']+'종족구성: '+spain_result['종족구성']+'국제전화: '+spain_result['국제전화']\n",
      "KeyError: '위치'\n",
      "Error while getting Updates: Conflict: terminated by other getUpdates request; make sure that only one bot instance is running\n",
      "No error handlers are registered, logging exception.\n",
      "Traceback (most recent call last):\n",
      "  File \"c:\\Users\\virtue\\anaconda3\\envs\\study\\lib\\site-packages\\telegram\\ext\\updater.py\", line 651, in _network_loop_retry\n",
      "    if not action_cb():\n",
      "  File \"c:\\Users\\virtue\\anaconda3\\envs\\study\\lib\\site-packages\\telegram\\ext\\updater.py\", line 602, in polling_action_cb\n",
      "    updates = self.bot.get_updates(\n",
      "  File \"c:\\Users\\virtue\\anaconda3\\envs\\study\\lib\\site-packages\\telegram\\ext\\extbot.py\", line 226, in get_updates\n",
      "    updates = super().get_updates(\n",
      "  File \"c:\\Users\\virtue\\anaconda3\\envs\\study\\lib\\site-packages\\telegram\\bot.py\", line 133, in decorator\n",
      "    result = func(*args, **kwargs)\n",
      "  File \"c:\\Users\\virtue\\anaconda3\\envs\\study\\lib\\site-packages\\telegram\\bot.py\", line 3057, in get_updates\n",
      "    self._post(\n",
      "  File \"c:\\Users\\virtue\\anaconda3\\envs\\study\\lib\\site-packages\\telegram\\bot.py\", line 298, in _post\n",
      "    return self.request.post(\n",
      "  File \"c:\\Users\\virtue\\anaconda3\\envs\\study\\lib\\site-packages\\telegram\\utils\\request.py\", line 361, in post\n",
      "    result = self._request_wrapper(\n",
      "  File \"c:\\Users\\virtue\\anaconda3\\envs\\study\\lib\\site-packages\\telegram\\utils\\request.py\", line 283, in _request_wrapper\n",
      "    raise Conflict(message)\n",
      "telegram.error.Conflict: Conflict: terminated by other getUpdates request; make sure that only one bot instance is running\n",
      "Error while getting Updates: Conflict: terminated by other getUpdates request; make sure that only one bot instance is running\n",
      "No error handlers are registered, logging exception.\n",
      "Traceback (most recent call last):\n",
      "  File \"c:\\Users\\virtue\\anaconda3\\envs\\study\\lib\\site-packages\\telegram\\ext\\updater.py\", line 651, in _network_loop_retry\n",
      "    if not action_cb():\n",
      "  File \"c:\\Users\\virtue\\anaconda3\\envs\\study\\lib\\site-packages\\telegram\\ext\\updater.py\", line 602, in polling_action_cb\n",
      "    updates = self.bot.get_updates(\n",
      "  File \"c:\\Users\\virtue\\anaconda3\\envs\\study\\lib\\site-packages\\telegram\\ext\\extbot.py\", line 226, in get_updates\n",
      "    updates = super().get_updates(\n",
      "  File \"c:\\Users\\virtue\\anaconda3\\envs\\study\\lib\\site-packages\\telegram\\bot.py\", line 133, in decorator\n",
      "    result = func(*args, **kwargs)\n",
      "  File \"c:\\Users\\virtue\\anaconda3\\envs\\study\\lib\\site-packages\\telegram\\bot.py\", line 3057, in get_updates\n",
      "    self._post(\n",
      "  File \"c:\\Users\\virtue\\anaconda3\\envs\\study\\lib\\site-packages\\telegram\\bot.py\", line 298, in _post\n",
      "    return self.request.post(\n",
      "  File \"c:\\Users\\virtue\\anaconda3\\envs\\study\\lib\\site-packages\\telegram\\utils\\request.py\", line 361, in post\n",
      "    result = self._request_wrapper(\n",
      "  File \"c:\\Users\\virtue\\anaconda3\\envs\\study\\lib\\site-packages\\telegram\\utils\\request.py\", line 283, in _request_wrapper\n",
      "    raise Conflict(message)\n",
      "telegram.error.Conflict: Conflict: terminated by other getUpdates request; make sure that only one bot instance is running\n",
      "Error while getting Updates: Conflict: terminated by other getUpdates request; make sure that only one bot instance is running\n",
      "No error handlers are registered, logging exception.\n",
      "Traceback (most recent call last):\n",
      "  File \"c:\\Users\\virtue\\anaconda3\\envs\\study\\lib\\site-packages\\telegram\\ext\\updater.py\", line 651, in _network_loop_retry\n",
      "    if not action_cb():\n",
      "  File \"c:\\Users\\virtue\\anaconda3\\envs\\study\\lib\\site-packages\\telegram\\ext\\updater.py\", line 602, in polling_action_cb\n",
      "    updates = self.bot.get_updates(\n",
      "  File \"c:\\Users\\virtue\\anaconda3\\envs\\study\\lib\\site-packages\\telegram\\ext\\extbot.py\", line 226, in get_updates\n",
      "    updates = super().get_updates(\n",
      "  File \"c:\\Users\\virtue\\anaconda3\\envs\\study\\lib\\site-packages\\telegram\\bot.py\", line 133, in decorator\n",
      "    result = func(*args, **kwargs)\n",
      "  File \"c:\\Users\\virtue\\anaconda3\\envs\\study\\lib\\site-packages\\telegram\\bot.py\", line 3057, in get_updates\n",
      "    self._post(\n",
      "  File \"c:\\Users\\virtue\\anaconda3\\envs\\study\\lib\\site-packages\\telegram\\bot.py\", line 298, in _post\n",
      "    return self.request.post(\n",
      "  File \"c:\\Users\\virtue\\anaconda3\\envs\\study\\lib\\site-packages\\telegram\\utils\\request.py\", line 361, in post\n",
      "    result = self._request_wrapper(\n",
      "  File \"c:\\Users\\virtue\\anaconda3\\envs\\study\\lib\\site-packages\\telegram\\utils\\request.py\", line 283, in _request_wrapper\n",
      "    raise Conflict(message)\n",
      "telegram.error.Conflict: Conflict: terminated by other getUpdates request; make sure that only one bot instance is running\n",
      "Error while getting Updates: Conflict: terminated by other getUpdates request; make sure that only one bot instance is running\n",
      "No error handlers are registered, logging exception.\n",
      "Traceback (most recent call last):\n",
      "  File \"c:\\Users\\virtue\\anaconda3\\envs\\study\\lib\\site-packages\\telegram\\ext\\updater.py\", line 651, in _network_loop_retry\n",
      "    if not action_cb():\n",
      "  File \"c:\\Users\\virtue\\anaconda3\\envs\\study\\lib\\site-packages\\telegram\\ext\\updater.py\", line 602, in polling_action_cb\n",
      "    updates = self.bot.get_updates(\n",
      "  File \"c:\\Users\\virtue\\anaconda3\\envs\\study\\lib\\site-packages\\telegram\\ext\\extbot.py\", line 226, in get_updates\n",
      "    updates = super().get_updates(\n",
      "  File \"c:\\Users\\virtue\\anaconda3\\envs\\study\\lib\\site-packages\\telegram\\bot.py\", line 133, in decorator\n",
      "    result = func(*args, **kwargs)\n",
      "  File \"c:\\Users\\virtue\\anaconda3\\envs\\study\\lib\\site-packages\\telegram\\bot.py\", line 3057, in get_updates\n",
      "    self._post(\n",
      "  File \"c:\\Users\\virtue\\anaconda3\\envs\\study\\lib\\site-packages\\telegram\\bot.py\", line 298, in _post\n",
      "    return self.request.post(\n",
      "  File \"c:\\Users\\virtue\\anaconda3\\envs\\study\\lib\\site-packages\\telegram\\utils\\request.py\", line 361, in post\n",
      "    result = self._request_wrapper(\n",
      "  File \"c:\\Users\\virtue\\anaconda3\\envs\\study\\lib\\site-packages\\telegram\\utils\\request.py\", line 283, in _request_wrapper\n",
      "    raise Conflict(message)\n",
      "telegram.error.Conflict: Conflict: terminated by other getUpdates request; make sure that only one bot instance is running\n",
      "Error while getting Updates: Conflict: terminated by other getUpdates request; make sure that only one bot instance is running\n",
      "No error handlers are registered, logging exception.\n",
      "Traceback (most recent call last):\n",
      "  File \"c:\\Users\\virtue\\anaconda3\\envs\\study\\lib\\site-packages\\telegram\\ext\\updater.py\", line 651, in _network_loop_retry\n",
      "    if not action_cb():\n",
      "  File \"c:\\Users\\virtue\\anaconda3\\envs\\study\\lib\\site-packages\\telegram\\ext\\updater.py\", line 602, in polling_action_cb\n",
      "    updates = self.bot.get_updates(\n",
      "  File \"c:\\Users\\virtue\\anaconda3\\envs\\study\\lib\\site-packages\\telegram\\ext\\extbot.py\", line 226, in get_updates\n",
      "    updates = super().get_updates(\n",
      "  File \"c:\\Users\\virtue\\anaconda3\\envs\\study\\lib\\site-packages\\telegram\\bot.py\", line 133, in decorator\n",
      "    result = func(*args, **kwargs)\n",
      "  File \"c:\\Users\\virtue\\anaconda3\\envs\\study\\lib\\site-packages\\telegram\\bot.py\", line 3057, in get_updates\n",
      "    self._post(\n",
      "  File \"c:\\Users\\virtue\\anaconda3\\envs\\study\\lib\\site-packages\\telegram\\bot.py\", line 298, in _post\n",
      "    return self.request.post(\n",
      "  File \"c:\\Users\\virtue\\anaconda3\\envs\\study\\lib\\site-packages\\telegram\\utils\\request.py\", line 361, in post\n",
      "    result = self._request_wrapper(\n",
      "  File \"c:\\Users\\virtue\\anaconda3\\envs\\study\\lib\\site-packages\\telegram\\utils\\request.py\", line 283, in _request_wrapper\n",
      "    raise Conflict(message)\n",
      "telegram.error.Conflict: Conflict: terminated by other getUpdates request; make sure that only one bot instance is running\n",
      "Error while getting Updates: Conflict: terminated by other getUpdates request; make sure that only one bot instance is running\n",
      "No error handlers are registered, logging exception.\n",
      "Traceback (most recent call last):\n",
      "  File \"c:\\Users\\virtue\\anaconda3\\envs\\study\\lib\\site-packages\\telegram\\ext\\updater.py\", line 651, in _network_loop_retry\n",
      "    if not action_cb():\n",
      "  File \"c:\\Users\\virtue\\anaconda3\\envs\\study\\lib\\site-packages\\telegram\\ext\\updater.py\", line 602, in polling_action_cb\n",
      "    updates = self.bot.get_updates(\n",
      "  File \"c:\\Users\\virtue\\anaconda3\\envs\\study\\lib\\site-packages\\telegram\\ext\\extbot.py\", line 226, in get_updates\n",
      "    updates = super().get_updates(\n",
      "  File \"c:\\Users\\virtue\\anaconda3\\envs\\study\\lib\\site-packages\\telegram\\bot.py\", line 133, in decorator\n",
      "    result = func(*args, **kwargs)\n",
      "  File \"c:\\Users\\virtue\\anaconda3\\envs\\study\\lib\\site-packages\\telegram\\bot.py\", line 3057, in get_updates\n",
      "    self._post(\n",
      "  File \"c:\\Users\\virtue\\anaconda3\\envs\\study\\lib\\site-packages\\telegram\\bot.py\", line 298, in _post\n",
      "    return self.request.post(\n",
      "  File \"c:\\Users\\virtue\\anaconda3\\envs\\study\\lib\\site-packages\\telegram\\utils\\request.py\", line 361, in post\n",
      "    result = self._request_wrapper(\n",
      "  File \"c:\\Users\\virtue\\anaconda3\\envs\\study\\lib\\site-packages\\telegram\\utils\\request.py\", line 283, in _request_wrapper\n",
      "    raise Conflict(message)\n",
      "telegram.error.Conflict: Conflict: terminated by other getUpdates request; make sure that only one bot instance is running\n",
      "Error while getting Updates: Conflict: terminated by other getUpdates request; make sure that only one bot instance is running\n",
      "No error handlers are registered, logging exception.\n",
      "Traceback (most recent call last):\n",
      "  File \"c:\\Users\\virtue\\anaconda3\\envs\\study\\lib\\site-packages\\telegram\\ext\\updater.py\", line 651, in _network_loop_retry\n",
      "    if not action_cb():\n",
      "  File \"c:\\Users\\virtue\\anaconda3\\envs\\study\\lib\\site-packages\\telegram\\ext\\updater.py\", line 602, in polling_action_cb\n",
      "    updates = self.bot.get_updates(\n",
      "  File \"c:\\Users\\virtue\\anaconda3\\envs\\study\\lib\\site-packages\\telegram\\ext\\extbot.py\", line 226, in get_updates\n",
      "    updates = super().get_updates(\n",
      "  File \"c:\\Users\\virtue\\anaconda3\\envs\\study\\lib\\site-packages\\telegram\\bot.py\", line 133, in decorator\n",
      "    result = func(*args, **kwargs)\n",
      "  File \"c:\\Users\\virtue\\anaconda3\\envs\\study\\lib\\site-packages\\telegram\\bot.py\", line 3057, in get_updates\n",
      "    self._post(\n",
      "  File \"c:\\Users\\virtue\\anaconda3\\envs\\study\\lib\\site-packages\\telegram\\bot.py\", line 298, in _post\n",
      "    return self.request.post(\n",
      "  File \"c:\\Users\\virtue\\anaconda3\\envs\\study\\lib\\site-packages\\telegram\\utils\\request.py\", line 361, in post\n",
      "    result = self._request_wrapper(\n",
      "  File \"c:\\Users\\virtue\\anaconda3\\envs\\study\\lib\\site-packages\\telegram\\utils\\request.py\", line 283, in _request_wrapper\n",
      "    raise Conflict(message)\n",
      "telegram.error.Conflict: Conflict: terminated by other getUpdates request; make sure that only one bot instance is running\n",
      "Error while getting Updates: Conflict: terminated by other getUpdates request; make sure that only one bot instance is running\n",
      "No error handlers are registered, logging exception.\n",
      "Traceback (most recent call last):\n",
      "  File \"c:\\Users\\virtue\\anaconda3\\envs\\study\\lib\\site-packages\\telegram\\ext\\updater.py\", line 651, in _network_loop_retry\n",
      "    if not action_cb():\n",
      "  File \"c:\\Users\\virtue\\anaconda3\\envs\\study\\lib\\site-packages\\telegram\\ext\\updater.py\", line 602, in polling_action_cb\n",
      "    updates = self.bot.get_updates(\n",
      "  File \"c:\\Users\\virtue\\anaconda3\\envs\\study\\lib\\site-packages\\telegram\\ext\\extbot.py\", line 226, in get_updates\n",
      "    updates = super().get_updates(\n",
      "  File \"c:\\Users\\virtue\\anaconda3\\envs\\study\\lib\\site-packages\\telegram\\bot.py\", line 133, in decorator\n",
      "    result = func(*args, **kwargs)\n",
      "  File \"c:\\Users\\virtue\\anaconda3\\envs\\study\\lib\\site-packages\\telegram\\bot.py\", line 3057, in get_updates\n",
      "    self._post(\n",
      "  File \"c:\\Users\\virtue\\anaconda3\\envs\\study\\lib\\site-packages\\telegram\\bot.py\", line 298, in _post\n",
      "    return self.request.post(\n",
      "  File \"c:\\Users\\virtue\\anaconda3\\envs\\study\\lib\\site-packages\\telegram\\utils\\request.py\", line 361, in post\n",
      "    result = self._request_wrapper(\n",
      "  File \"c:\\Users\\virtue\\anaconda3\\envs\\study\\lib\\site-packages\\telegram\\utils\\request.py\", line 283, in _request_wrapper\n",
      "    raise Conflict(message)\n",
      "telegram.error.Conflict: Conflict: terminated by other getUpdates request; make sure that only one bot instance is running\n",
      "Error while getting Updates: Conflict: terminated by other getUpdates request; make sure that only one bot instance is running\n",
      "No error handlers are registered, logging exception.\n",
      "Traceback (most recent call last):\n",
      "  File \"c:\\Users\\virtue\\anaconda3\\envs\\study\\lib\\site-packages\\telegram\\ext\\updater.py\", line 651, in _network_loop_retry\n",
      "    if not action_cb():\n",
      "  File \"c:\\Users\\virtue\\anaconda3\\envs\\study\\lib\\site-packages\\telegram\\ext\\updater.py\", line 602, in polling_action_cb\n",
      "    updates = self.bot.get_updates(\n",
      "  File \"c:\\Users\\virtue\\anaconda3\\envs\\study\\lib\\site-packages\\telegram\\ext\\extbot.py\", line 226, in get_updates\n",
      "    updates = super().get_updates(\n",
      "  File \"c:\\Users\\virtue\\anaconda3\\envs\\study\\lib\\site-packages\\telegram\\bot.py\", line 133, in decorator\n",
      "    result = func(*args, **kwargs)\n",
      "  File \"c:\\Users\\virtue\\anaconda3\\envs\\study\\lib\\site-packages\\telegram\\bot.py\", line 3057, in get_updates\n",
      "    self._post(\n",
      "  File \"c:\\Users\\virtue\\anaconda3\\envs\\study\\lib\\site-packages\\telegram\\bot.py\", line 298, in _post\n",
      "    return self.request.post(\n",
      "  File \"c:\\Users\\virtue\\anaconda3\\envs\\study\\lib\\site-packages\\telegram\\utils\\request.py\", line 361, in post\n",
      "    result = self._request_wrapper(\n",
      "  File \"c:\\Users\\virtue\\anaconda3\\envs\\study\\lib\\site-packages\\telegram\\utils\\request.py\", line 283, in _request_wrapper\n",
      "    raise Conflict(message)\n",
      "telegram.error.Conflict: Conflict: terminated by other getUpdates request; make sure that only one bot instance is running\n",
      "Error while getting Updates: Conflict: terminated by other getUpdates request; make sure that only one bot instance is running\n",
      "No error handlers are registered, logging exception.\n",
      "Traceback (most recent call last):\n",
      "  File \"c:\\Users\\virtue\\anaconda3\\envs\\study\\lib\\site-packages\\telegram\\ext\\updater.py\", line 651, in _network_loop_retry\n",
      "    if not action_cb():\n",
      "  File \"c:\\Users\\virtue\\anaconda3\\envs\\study\\lib\\site-packages\\telegram\\ext\\updater.py\", line 602, in polling_action_cb\n",
      "    updates = self.bot.get_updates(\n",
      "  File \"c:\\Users\\virtue\\anaconda3\\envs\\study\\lib\\site-packages\\telegram\\ext\\extbot.py\", line 226, in get_updates\n",
      "    updates = super().get_updates(\n",
      "  File \"c:\\Users\\virtue\\anaconda3\\envs\\study\\lib\\site-packages\\telegram\\bot.py\", line 133, in decorator\n",
      "    result = func(*args, **kwargs)\n",
      "  File \"c:\\Users\\virtue\\anaconda3\\envs\\study\\lib\\site-packages\\telegram\\bot.py\", line 3057, in get_updates\n",
      "    self._post(\n",
      "  File \"c:\\Users\\virtue\\anaconda3\\envs\\study\\lib\\site-packages\\telegram\\bot.py\", line 298, in _post\n",
      "    return self.request.post(\n",
      "  File \"c:\\Users\\virtue\\anaconda3\\envs\\study\\lib\\site-packages\\telegram\\utils\\request.py\", line 361, in post\n",
      "    result = self._request_wrapper(\n",
      "  File \"c:\\Users\\virtue\\anaconda3\\envs\\study\\lib\\site-packages\\telegram\\utils\\request.py\", line 283, in _request_wrapper\n",
      "    raise Conflict(message)\n",
      "telegram.error.Conflict: Conflict: terminated by other getUpdates request; make sure that only one bot instance is running\n",
      "Error while getting Updates: Conflict: terminated by other getUpdates request; make sure that only one bot instance is running\n",
      "No error handlers are registered, logging exception.\n",
      "Traceback (most recent call last):\n",
      "  File \"c:\\Users\\virtue\\anaconda3\\envs\\study\\lib\\site-packages\\telegram\\ext\\updater.py\", line 651, in _network_loop_retry\n",
      "    if not action_cb():\n",
      "  File \"c:\\Users\\virtue\\anaconda3\\envs\\study\\lib\\site-packages\\telegram\\ext\\updater.py\", line 602, in polling_action_cb\n",
      "    updates = self.bot.get_updates(\n",
      "  File \"c:\\Users\\virtue\\anaconda3\\envs\\study\\lib\\site-packages\\telegram\\ext\\extbot.py\", line 226, in get_updates\n",
      "    updates = super().get_updates(\n",
      "  File \"c:\\Users\\virtue\\anaconda3\\envs\\study\\lib\\site-packages\\telegram\\bot.py\", line 133, in decorator\n",
      "    result = func(*args, **kwargs)\n",
      "  File \"c:\\Users\\virtue\\anaconda3\\envs\\study\\lib\\site-packages\\telegram\\bot.py\", line 3057, in get_updates\n",
      "    self._post(\n",
      "  File \"c:\\Users\\virtue\\anaconda3\\envs\\study\\lib\\site-packages\\telegram\\bot.py\", line 298, in _post\n",
      "    return self.request.post(\n",
      "  File \"c:\\Users\\virtue\\anaconda3\\envs\\study\\lib\\site-packages\\telegram\\utils\\request.py\", line 361, in post\n",
      "    result = self._request_wrapper(\n",
      "  File \"c:\\Users\\virtue\\anaconda3\\envs\\study\\lib\\site-packages\\telegram\\utils\\request.py\", line 283, in _request_wrapper\n",
      "    raise Conflict(message)\n",
      "telegram.error.Conflict: Conflict: terminated by other getUpdates request; make sure that only one bot instance is running\n",
      "Error while getting Updates: Conflict: terminated by other getUpdates request; make sure that only one bot instance is running\n",
      "No error handlers are registered, logging exception.\n",
      "Traceback (most recent call last):\n",
      "  File \"c:\\Users\\virtue\\anaconda3\\envs\\study\\lib\\site-packages\\telegram\\ext\\updater.py\", line 651, in _network_loop_retry\n",
      "    if not action_cb():\n",
      "  File \"c:\\Users\\virtue\\anaconda3\\envs\\study\\lib\\site-packages\\telegram\\ext\\updater.py\", line 602, in polling_action_cb\n",
      "    updates = self.bot.get_updates(\n",
      "  File \"c:\\Users\\virtue\\anaconda3\\envs\\study\\lib\\site-packages\\telegram\\ext\\extbot.py\", line 226, in get_updates\n",
      "    updates = super().get_updates(\n",
      "  File \"c:\\Users\\virtue\\anaconda3\\envs\\study\\lib\\site-packages\\telegram\\bot.py\", line 133, in decorator\n",
      "    result = func(*args, **kwargs)\n",
      "  File \"c:\\Users\\virtue\\anaconda3\\envs\\study\\lib\\site-packages\\telegram\\bot.py\", line 3057, in get_updates\n",
      "    self._post(\n",
      "  File \"c:\\Users\\virtue\\anaconda3\\envs\\study\\lib\\site-packages\\telegram\\bot.py\", line 298, in _post\n",
      "    return self.request.post(\n",
      "  File \"c:\\Users\\virtue\\anaconda3\\envs\\study\\lib\\site-packages\\telegram\\utils\\request.py\", line 361, in post\n",
      "    result = self._request_wrapper(\n",
      "  File \"c:\\Users\\virtue\\anaconda3\\envs\\study\\lib\\site-packages\\telegram\\utils\\request.py\", line 283, in _request_wrapper\n",
      "    raise Conflict(message)\n",
      "telegram.error.Conflict: Conflict: terminated by other getUpdates request; make sure that only one bot instance is running\n",
      "Error while getting Updates: Conflict: terminated by other getUpdates request; make sure that only one bot instance is running\n",
      "No error handlers are registered, logging exception.\n",
      "Traceback (most recent call last):\n",
      "  File \"c:\\Users\\virtue\\anaconda3\\envs\\study\\lib\\site-packages\\telegram\\ext\\updater.py\", line 651, in _network_loop_retry\n",
      "    if not action_cb():\n",
      "  File \"c:\\Users\\virtue\\anaconda3\\envs\\study\\lib\\site-packages\\telegram\\ext\\updater.py\", line 602, in polling_action_cb\n",
      "    updates = self.bot.get_updates(\n",
      "  File \"c:\\Users\\virtue\\anaconda3\\envs\\study\\lib\\site-packages\\telegram\\ext\\extbot.py\", line 226, in get_updates\n",
      "    updates = super().get_updates(\n",
      "  File \"c:\\Users\\virtue\\anaconda3\\envs\\study\\lib\\site-packages\\telegram\\bot.py\", line 133, in decorator\n",
      "    result = func(*args, **kwargs)\n",
      "  File \"c:\\Users\\virtue\\anaconda3\\envs\\study\\lib\\site-packages\\telegram\\bot.py\", line 3057, in get_updates\n",
      "    self._post(\n",
      "  File \"c:\\Users\\virtue\\anaconda3\\envs\\study\\lib\\site-packages\\telegram\\bot.py\", line 298, in _post\n",
      "    return self.request.post(\n",
      "  File \"c:\\Users\\virtue\\anaconda3\\envs\\study\\lib\\site-packages\\telegram\\utils\\request.py\", line 361, in post\n",
      "    result = self._request_wrapper(\n",
      "  File \"c:\\Users\\virtue\\anaconda3\\envs\\study\\lib\\site-packages\\telegram\\utils\\request.py\", line 283, in _request_wrapper\n",
      "    raise Conflict(message)\n",
      "telegram.error.Conflict: Conflict: terminated by other getUpdates request; make sure that only one bot instance is running\n",
      "Error while getting Updates: Conflict: terminated by other getUpdates request; make sure that only one bot instance is running\n",
      "No error handlers are registered, logging exception.\n",
      "Traceback (most recent call last):\n",
      "  File \"c:\\Users\\virtue\\anaconda3\\envs\\study\\lib\\site-packages\\telegram\\ext\\updater.py\", line 651, in _network_loop_retry\n",
      "    if not action_cb():\n",
      "  File \"c:\\Users\\virtue\\anaconda3\\envs\\study\\lib\\site-packages\\telegram\\ext\\updater.py\", line 602, in polling_action_cb\n",
      "    updates = self.bot.get_updates(\n",
      "  File \"c:\\Users\\virtue\\anaconda3\\envs\\study\\lib\\site-packages\\telegram\\ext\\extbot.py\", line 226, in get_updates\n",
      "    updates = super().get_updates(\n",
      "  File \"c:\\Users\\virtue\\anaconda3\\envs\\study\\lib\\site-packages\\telegram\\bot.py\", line 133, in decorator\n",
      "    result = func(*args, **kwargs)\n",
      "  File \"c:\\Users\\virtue\\anaconda3\\envs\\study\\lib\\site-packages\\telegram\\bot.py\", line 3057, in get_updates\n",
      "    self._post(\n",
      "  File \"c:\\Users\\virtue\\anaconda3\\envs\\study\\lib\\site-packages\\telegram\\bot.py\", line 298, in _post\n",
      "    return self.request.post(\n",
      "  File \"c:\\Users\\virtue\\anaconda3\\envs\\study\\lib\\site-packages\\telegram\\utils\\request.py\", line 361, in post\n",
      "    result = self._request_wrapper(\n",
      "  File \"c:\\Users\\virtue\\anaconda3\\envs\\study\\lib\\site-packages\\telegram\\utils\\request.py\", line 283, in _request_wrapper\n",
      "    raise Conflict(message)\n",
      "telegram.error.Conflict: Conflict: terminated by other getUpdates request; make sure that only one bot instance is running\n",
      "Error while getting Updates: Conflict: terminated by other getUpdates request; make sure that only one bot instance is running\n",
      "No error handlers are registered, logging exception.\n",
      "Traceback (most recent call last):\n",
      "  File \"c:\\Users\\virtue\\anaconda3\\envs\\study\\lib\\site-packages\\telegram\\ext\\updater.py\", line 651, in _network_loop_retry\n",
      "    if not action_cb():\n",
      "  File \"c:\\Users\\virtue\\anaconda3\\envs\\study\\lib\\site-packages\\telegram\\ext\\updater.py\", line 602, in polling_action_cb\n",
      "    updates = self.bot.get_updates(\n",
      "  File \"c:\\Users\\virtue\\anaconda3\\envs\\study\\lib\\site-packages\\telegram\\ext\\extbot.py\", line 226, in get_updates\n",
      "    updates = super().get_updates(\n",
      "  File \"c:\\Users\\virtue\\anaconda3\\envs\\study\\lib\\site-packages\\telegram\\bot.py\", line 133, in decorator\n",
      "    result = func(*args, **kwargs)\n",
      "  File \"c:\\Users\\virtue\\anaconda3\\envs\\study\\lib\\site-packages\\telegram\\bot.py\", line 3057, in get_updates\n",
      "    self._post(\n",
      "  File \"c:\\Users\\virtue\\anaconda3\\envs\\study\\lib\\site-packages\\telegram\\bot.py\", line 298, in _post\n",
      "    return self.request.post(\n",
      "  File \"c:\\Users\\virtue\\anaconda3\\envs\\study\\lib\\site-packages\\telegram\\utils\\request.py\", line 361, in post\n",
      "    result = self._request_wrapper(\n",
      "  File \"c:\\Users\\virtue\\anaconda3\\envs\\study\\lib\\site-packages\\telegram\\utils\\request.py\", line 283, in _request_wrapper\n",
      "    raise Conflict(message)\n",
      "telegram.error.Conflict: Conflict: terminated by other getUpdates request; make sure that only one bot instance is running\n",
      "Error while getting Updates: Conflict: terminated by other getUpdates request; make sure that only one bot instance is running\n",
      "No error handlers are registered, logging exception.\n",
      "Traceback (most recent call last):\n",
      "  File \"c:\\Users\\virtue\\anaconda3\\envs\\study\\lib\\site-packages\\telegram\\ext\\updater.py\", line 651, in _network_loop_retry\n",
      "    if not action_cb():\n",
      "  File \"c:\\Users\\virtue\\anaconda3\\envs\\study\\lib\\site-packages\\telegram\\ext\\updater.py\", line 602, in polling_action_cb\n",
      "    updates = self.bot.get_updates(\n",
      "  File \"c:\\Users\\virtue\\anaconda3\\envs\\study\\lib\\site-packages\\telegram\\ext\\extbot.py\", line 226, in get_updates\n",
      "    updates = super().get_updates(\n",
      "  File \"c:\\Users\\virtue\\anaconda3\\envs\\study\\lib\\site-packages\\telegram\\bot.py\", line 133, in decorator\n",
      "    result = func(*args, **kwargs)\n",
      "  File \"c:\\Users\\virtue\\anaconda3\\envs\\study\\lib\\site-packages\\telegram\\bot.py\", line 3057, in get_updates\n",
      "    self._post(\n",
      "  File \"c:\\Users\\virtue\\anaconda3\\envs\\study\\lib\\site-packages\\telegram\\bot.py\", line 298, in _post\n",
      "    return self.request.post(\n",
      "  File \"c:\\Users\\virtue\\anaconda3\\envs\\study\\lib\\site-packages\\telegram\\utils\\request.py\", line 361, in post\n",
      "    result = self._request_wrapper(\n",
      "  File \"c:\\Users\\virtue\\anaconda3\\envs\\study\\lib\\site-packages\\telegram\\utils\\request.py\", line 283, in _request_wrapper\n",
      "    raise Conflict(message)\n",
      "telegram.error.Conflict: Conflict: terminated by other getUpdates request; make sure that only one bot instance is running\n",
      "Error while getting Updates: Conflict: terminated by other getUpdates request; make sure that only one bot instance is running\n",
      "No error handlers are registered, logging exception.\n",
      "Traceback (most recent call last):\n",
      "  File \"c:\\Users\\virtue\\anaconda3\\envs\\study\\lib\\site-packages\\telegram\\ext\\updater.py\", line 651, in _network_loop_retry\n",
      "    if not action_cb():\n",
      "  File \"c:\\Users\\virtue\\anaconda3\\envs\\study\\lib\\site-packages\\telegram\\ext\\updater.py\", line 602, in polling_action_cb\n",
      "    updates = self.bot.get_updates(\n",
      "  File \"c:\\Users\\virtue\\anaconda3\\envs\\study\\lib\\site-packages\\telegram\\ext\\extbot.py\", line 226, in get_updates\n",
      "    updates = super().get_updates(\n",
      "  File \"c:\\Users\\virtue\\anaconda3\\envs\\study\\lib\\site-packages\\telegram\\bot.py\", line 133, in decorator\n",
      "    result = func(*args, **kwargs)\n",
      "  File \"c:\\Users\\virtue\\anaconda3\\envs\\study\\lib\\site-packages\\telegram\\bot.py\", line 3057, in get_updates\n",
      "    self._post(\n",
      "  File \"c:\\Users\\virtue\\anaconda3\\envs\\study\\lib\\site-packages\\telegram\\bot.py\", line 298, in _post\n",
      "    return self.request.post(\n",
      "  File \"c:\\Users\\virtue\\anaconda3\\envs\\study\\lib\\site-packages\\telegram\\utils\\request.py\", line 361, in post\n",
      "    result = self._request_wrapper(\n",
      "  File \"c:\\Users\\virtue\\anaconda3\\envs\\study\\lib\\site-packages\\telegram\\utils\\request.py\", line 283, in _request_wrapper\n",
      "    raise Conflict(message)\n",
      "telegram.error.Conflict: Conflict: terminated by other getUpdates request; make sure that only one bot instance is running\n",
      "Error while getting Updates: Conflict: terminated by other getUpdates request; make sure that only one bot instance is running\n",
      "No error handlers are registered, logging exception.\n",
      "Traceback (most recent call last):\n",
      "  File \"c:\\Users\\virtue\\anaconda3\\envs\\study\\lib\\site-packages\\telegram\\ext\\updater.py\", line 651, in _network_loop_retry\n",
      "    if not action_cb():\n",
      "  File \"c:\\Users\\virtue\\anaconda3\\envs\\study\\lib\\site-packages\\telegram\\ext\\updater.py\", line 602, in polling_action_cb\n",
      "    updates = self.bot.get_updates(\n",
      "  File \"c:\\Users\\virtue\\anaconda3\\envs\\study\\lib\\site-packages\\telegram\\ext\\extbot.py\", line 226, in get_updates\n",
      "    updates = super().get_updates(\n",
      "  File \"c:\\Users\\virtue\\anaconda3\\envs\\study\\lib\\site-packages\\telegram\\bot.py\", line 133, in decorator\n",
      "    result = func(*args, **kwargs)\n",
      "  File \"c:\\Users\\virtue\\anaconda3\\envs\\study\\lib\\site-packages\\telegram\\bot.py\", line 3057, in get_updates\n",
      "    self._post(\n",
      "  File \"c:\\Users\\virtue\\anaconda3\\envs\\study\\lib\\site-packages\\telegram\\bot.py\", line 298, in _post\n",
      "    return self.request.post(\n",
      "  File \"c:\\Users\\virtue\\anaconda3\\envs\\study\\lib\\site-packages\\telegram\\utils\\request.py\", line 361, in post\n",
      "    result = self._request_wrapper(\n",
      "  File \"c:\\Users\\virtue\\anaconda3\\envs\\study\\lib\\site-packages\\telegram\\utils\\request.py\", line 283, in _request_wrapper\n",
      "    raise Conflict(message)\n",
      "telegram.error.Conflict: Conflict: terminated by other getUpdates request; make sure that only one bot instance is running\n",
      "Error while getting Updates: Conflict: terminated by other getUpdates request; make sure that only one bot instance is running\n",
      "No error handlers are registered, logging exception.\n",
      "Traceback (most recent call last):\n",
      "  File \"c:\\Users\\virtue\\anaconda3\\envs\\study\\lib\\site-packages\\telegram\\ext\\updater.py\", line 651, in _network_loop_retry\n",
      "    if not action_cb():\n",
      "  File \"c:\\Users\\virtue\\anaconda3\\envs\\study\\lib\\site-packages\\telegram\\ext\\updater.py\", line 602, in polling_action_cb\n",
      "    updates = self.bot.get_updates(\n",
      "  File \"c:\\Users\\virtue\\anaconda3\\envs\\study\\lib\\site-packages\\telegram\\ext\\extbot.py\", line 226, in get_updates\n",
      "    updates = super().get_updates(\n",
      "  File \"c:\\Users\\virtue\\anaconda3\\envs\\study\\lib\\site-packages\\telegram\\bot.py\", line 133, in decorator\n",
      "    result = func(*args, **kwargs)\n",
      "  File \"c:\\Users\\virtue\\anaconda3\\envs\\study\\lib\\site-packages\\telegram\\bot.py\", line 3057, in get_updates\n",
      "    self._post(\n",
      "  File \"c:\\Users\\virtue\\anaconda3\\envs\\study\\lib\\site-packages\\telegram\\bot.py\", line 298, in _post\n",
      "    return self.request.post(\n",
      "  File \"c:\\Users\\virtue\\anaconda3\\envs\\study\\lib\\site-packages\\telegram\\utils\\request.py\", line 361, in post\n",
      "    result = self._request_wrapper(\n",
      "  File \"c:\\Users\\virtue\\anaconda3\\envs\\study\\lib\\site-packages\\telegram\\utils\\request.py\", line 283, in _request_wrapper\n",
      "    raise Conflict(message)\n",
      "telegram.error.Conflict: Conflict: terminated by other getUpdates request; make sure that only one bot instance is running\n",
      "Error while getting Updates: Conflict: terminated by other getUpdates request; make sure that only one bot instance is running\n",
      "No error handlers are registered, logging exception.\n",
      "Traceback (most recent call last):\n",
      "  File \"c:\\Users\\virtue\\anaconda3\\envs\\study\\lib\\site-packages\\telegram\\ext\\updater.py\", line 651, in _network_loop_retry\n",
      "    if not action_cb():\n",
      "  File \"c:\\Users\\virtue\\anaconda3\\envs\\study\\lib\\site-packages\\telegram\\ext\\updater.py\", line 602, in polling_action_cb\n",
      "    updates = self.bot.get_updates(\n",
      "  File \"c:\\Users\\virtue\\anaconda3\\envs\\study\\lib\\site-packages\\telegram\\ext\\extbot.py\", line 226, in get_updates\n",
      "    updates = super().get_updates(\n",
      "  File \"c:\\Users\\virtue\\anaconda3\\envs\\study\\lib\\site-packages\\telegram\\bot.py\", line 133, in decorator\n",
      "    result = func(*args, **kwargs)\n",
      "  File \"c:\\Users\\virtue\\anaconda3\\envs\\study\\lib\\site-packages\\telegram\\bot.py\", line 3057, in get_updates\n",
      "    self._post(\n",
      "  File \"c:\\Users\\virtue\\anaconda3\\envs\\study\\lib\\site-packages\\telegram\\bot.py\", line 298, in _post\n",
      "    return self.request.post(\n",
      "  File \"c:\\Users\\virtue\\anaconda3\\envs\\study\\lib\\site-packages\\telegram\\utils\\request.py\", line 361, in post\n",
      "    result = self._request_wrapper(\n",
      "  File \"c:\\Users\\virtue\\anaconda3\\envs\\study\\lib\\site-packages\\telegram\\utils\\request.py\", line 283, in _request_wrapper\n",
      "    raise Conflict(message)\n",
      "telegram.error.Conflict: Conflict: terminated by other getUpdates request; make sure that only one bot instance is running\n",
      "Error while getting Updates: Conflict: terminated by other getUpdates request; make sure that only one bot instance is running\n",
      "No error handlers are registered, logging exception.\n",
      "Traceback (most recent call last):\n",
      "  File \"c:\\Users\\virtue\\anaconda3\\envs\\study\\lib\\site-packages\\telegram\\ext\\updater.py\", line 651, in _network_loop_retry\n",
      "    if not action_cb():\n",
      "  File \"c:\\Users\\virtue\\anaconda3\\envs\\study\\lib\\site-packages\\telegram\\ext\\updater.py\", line 602, in polling_action_cb\n",
      "    updates = self.bot.get_updates(\n",
      "  File \"c:\\Users\\virtue\\anaconda3\\envs\\study\\lib\\site-packages\\telegram\\ext\\extbot.py\", line 226, in get_updates\n",
      "    updates = super().get_updates(\n",
      "  File \"c:\\Users\\virtue\\anaconda3\\envs\\study\\lib\\site-packages\\telegram\\bot.py\", line 133, in decorator\n",
      "    result = func(*args, **kwargs)\n",
      "  File \"c:\\Users\\virtue\\anaconda3\\envs\\study\\lib\\site-packages\\telegram\\bot.py\", line 3057, in get_updates\n",
      "    self._post(\n",
      "  File \"c:\\Users\\virtue\\anaconda3\\envs\\study\\lib\\site-packages\\telegram\\bot.py\", line 298, in _post\n",
      "    return self.request.post(\n",
      "  File \"c:\\Users\\virtue\\anaconda3\\envs\\study\\lib\\site-packages\\telegram\\utils\\request.py\", line 361, in post\n",
      "    result = self._request_wrapper(\n",
      "  File \"c:\\Users\\virtue\\anaconda3\\envs\\study\\lib\\site-packages\\telegram\\utils\\request.py\", line 283, in _request_wrapper\n",
      "    raise Conflict(message)\n",
      "telegram.error.Conflict: Conflict: terminated by other getUpdates request; make sure that only one bot instance is running\n",
      "Error while getting Updates: Conflict: terminated by other getUpdates request; make sure that only one bot instance is running\n",
      "No error handlers are registered, logging exception.\n",
      "Traceback (most recent call last):\n",
      "  File \"c:\\Users\\virtue\\anaconda3\\envs\\study\\lib\\site-packages\\telegram\\ext\\updater.py\", line 651, in _network_loop_retry\n",
      "    if not action_cb():\n",
      "  File \"c:\\Users\\virtue\\anaconda3\\envs\\study\\lib\\site-packages\\telegram\\ext\\updater.py\", line 602, in polling_action_cb\n",
      "    updates = self.bot.get_updates(\n",
      "  File \"c:\\Users\\virtue\\anaconda3\\envs\\study\\lib\\site-packages\\telegram\\ext\\extbot.py\", line 226, in get_updates\n",
      "    updates = super().get_updates(\n",
      "  File \"c:\\Users\\virtue\\anaconda3\\envs\\study\\lib\\site-packages\\telegram\\bot.py\", line 133, in decorator\n",
      "    result = func(*args, **kwargs)\n",
      "  File \"c:\\Users\\virtue\\anaconda3\\envs\\study\\lib\\site-packages\\telegram\\bot.py\", line 3057, in get_updates\n",
      "    self._post(\n",
      "  File \"c:\\Users\\virtue\\anaconda3\\envs\\study\\lib\\site-packages\\telegram\\bot.py\", line 298, in _post\n",
      "    return self.request.post(\n",
      "  File \"c:\\Users\\virtue\\anaconda3\\envs\\study\\lib\\site-packages\\telegram\\utils\\request.py\", line 361, in post\n",
      "    result = self._request_wrapper(\n",
      "  File \"c:\\Users\\virtue\\anaconda3\\envs\\study\\lib\\site-packages\\telegram\\utils\\request.py\", line 283, in _request_wrapper\n",
      "    raise Conflict(message)\n",
      "telegram.error.Conflict: Conflict: terminated by other getUpdates request; make sure that only one bot instance is running\n",
      "Error while getting Updates: Conflict: terminated by other getUpdates request; make sure that only one bot instance is running\n",
      "No error handlers are registered, logging exception.\n",
      "Traceback (most recent call last):\n",
      "  File \"c:\\Users\\virtue\\anaconda3\\envs\\study\\lib\\site-packages\\telegram\\ext\\updater.py\", line 651, in _network_loop_retry\n",
      "    if not action_cb():\n",
      "  File \"c:\\Users\\virtue\\anaconda3\\envs\\study\\lib\\site-packages\\telegram\\ext\\updater.py\", line 602, in polling_action_cb\n",
      "    updates = self.bot.get_updates(\n",
      "  File \"c:\\Users\\virtue\\anaconda3\\envs\\study\\lib\\site-packages\\telegram\\ext\\extbot.py\", line 226, in get_updates\n",
      "    updates = super().get_updates(\n",
      "  File \"c:\\Users\\virtue\\anaconda3\\envs\\study\\lib\\site-packages\\telegram\\bot.py\", line 133, in decorator\n",
      "    result = func(*args, **kwargs)\n",
      "  File \"c:\\Users\\virtue\\anaconda3\\envs\\study\\lib\\site-packages\\telegram\\bot.py\", line 3057, in get_updates\n",
      "    self._post(\n",
      "  File \"c:\\Users\\virtue\\anaconda3\\envs\\study\\lib\\site-packages\\telegram\\bot.py\", line 298, in _post\n",
      "    return self.request.post(\n",
      "  File \"c:\\Users\\virtue\\anaconda3\\envs\\study\\lib\\site-packages\\telegram\\utils\\request.py\", line 361, in post\n",
      "    result = self._request_wrapper(\n",
      "  File \"c:\\Users\\virtue\\anaconda3\\envs\\study\\lib\\site-packages\\telegram\\utils\\request.py\", line 283, in _request_wrapper\n",
      "    raise Conflict(message)\n",
      "telegram.error.Conflict: Conflict: terminated by other getUpdates request; make sure that only one bot instance is running\n",
      "Error while getting Updates: Conflict: terminated by other getUpdates request; make sure that only one bot instance is running\n",
      "No error handlers are registered, logging exception.\n",
      "Traceback (most recent call last):\n",
      "  File \"c:\\Users\\virtue\\anaconda3\\envs\\study\\lib\\site-packages\\telegram\\ext\\updater.py\", line 651, in _network_loop_retry\n",
      "    if not action_cb():\n",
      "  File \"c:\\Users\\virtue\\anaconda3\\envs\\study\\lib\\site-packages\\telegram\\ext\\updater.py\", line 602, in polling_action_cb\n",
      "    updates = self.bot.get_updates(\n",
      "  File \"c:\\Users\\virtue\\anaconda3\\envs\\study\\lib\\site-packages\\telegram\\ext\\extbot.py\", line 226, in get_updates\n",
      "    updates = super().get_updates(\n",
      "  File \"c:\\Users\\virtue\\anaconda3\\envs\\study\\lib\\site-packages\\telegram\\bot.py\", line 133, in decorator\n",
      "    result = func(*args, **kwargs)\n",
      "  File \"c:\\Users\\virtue\\anaconda3\\envs\\study\\lib\\site-packages\\telegram\\bot.py\", line 3057, in get_updates\n",
      "    self._post(\n",
      "  File \"c:\\Users\\virtue\\anaconda3\\envs\\study\\lib\\site-packages\\telegram\\bot.py\", line 298, in _post\n",
      "    return self.request.post(\n",
      "  File \"c:\\Users\\virtue\\anaconda3\\envs\\study\\lib\\site-packages\\telegram\\utils\\request.py\", line 361, in post\n",
      "    result = self._request_wrapper(\n",
      "  File \"c:\\Users\\virtue\\anaconda3\\envs\\study\\lib\\site-packages\\telegram\\utils\\request.py\", line 283, in _request_wrapper\n",
      "    raise Conflict(message)\n",
      "telegram.error.Conflict: Conflict: terminated by other getUpdates request; make sure that only one bot instance is running\n",
      "Error while getting Updates: Conflict: terminated by other getUpdates request; make sure that only one bot instance is running\n",
      "No error handlers are registered, logging exception.\n",
      "Traceback (most recent call last):\n",
      "  File \"c:\\Users\\virtue\\anaconda3\\envs\\study\\lib\\site-packages\\telegram\\ext\\updater.py\", line 651, in _network_loop_retry\n",
      "    if not action_cb():\n",
      "  File \"c:\\Users\\virtue\\anaconda3\\envs\\study\\lib\\site-packages\\telegram\\ext\\updater.py\", line 602, in polling_action_cb\n",
      "    updates = self.bot.get_updates(\n",
      "  File \"c:\\Users\\virtue\\anaconda3\\envs\\study\\lib\\site-packages\\telegram\\ext\\extbot.py\", line 226, in get_updates\n",
      "    updates = super().get_updates(\n",
      "  File \"c:\\Users\\virtue\\anaconda3\\envs\\study\\lib\\site-packages\\telegram\\bot.py\", line 133, in decorator\n",
      "    result = func(*args, **kwargs)\n",
      "  File \"c:\\Users\\virtue\\anaconda3\\envs\\study\\lib\\site-packages\\telegram\\bot.py\", line 3057, in get_updates\n",
      "    self._post(\n",
      "  File \"c:\\Users\\virtue\\anaconda3\\envs\\study\\lib\\site-packages\\telegram\\bot.py\", line 298, in _post\n",
      "    return self.request.post(\n",
      "  File \"c:\\Users\\virtue\\anaconda3\\envs\\study\\lib\\site-packages\\telegram\\utils\\request.py\", line 361, in post\n",
      "    result = self._request_wrapper(\n",
      "  File \"c:\\Users\\virtue\\anaconda3\\envs\\study\\lib\\site-packages\\telegram\\utils\\request.py\", line 283, in _request_wrapper\n",
      "    raise Conflict(message)\n",
      "telegram.error.Conflict: Conflict: terminated by other getUpdates request; make sure that only one bot instance is running\n",
      "Error while getting Updates: Conflict: terminated by other getUpdates request; make sure that only one bot instance is running\n",
      "No error handlers are registered, logging exception.\n",
      "Traceback (most recent call last):\n",
      "  File \"c:\\Users\\virtue\\anaconda3\\envs\\study\\lib\\site-packages\\telegram\\ext\\updater.py\", line 651, in _network_loop_retry\n",
      "    if not action_cb():\n",
      "  File \"c:\\Users\\virtue\\anaconda3\\envs\\study\\lib\\site-packages\\telegram\\ext\\updater.py\", line 602, in polling_action_cb\n",
      "    updates = self.bot.get_updates(\n",
      "  File \"c:\\Users\\virtue\\anaconda3\\envs\\study\\lib\\site-packages\\telegram\\ext\\extbot.py\", line 226, in get_updates\n",
      "    updates = super().get_updates(\n",
      "  File \"c:\\Users\\virtue\\anaconda3\\envs\\study\\lib\\site-packages\\telegram\\bot.py\", line 133, in decorator\n",
      "    result = func(*args, **kwargs)\n",
      "  File \"c:\\Users\\virtue\\anaconda3\\envs\\study\\lib\\site-packages\\telegram\\bot.py\", line 3057, in get_updates\n",
      "    self._post(\n",
      "  File \"c:\\Users\\virtue\\anaconda3\\envs\\study\\lib\\site-packages\\telegram\\bot.py\", line 298, in _post\n",
      "    return self.request.post(\n",
      "  File \"c:\\Users\\virtue\\anaconda3\\envs\\study\\lib\\site-packages\\telegram\\utils\\request.py\", line 361, in post\n",
      "    result = self._request_wrapper(\n",
      "  File \"c:\\Users\\virtue\\anaconda3\\envs\\study\\lib\\site-packages\\telegram\\utils\\request.py\", line 283, in _request_wrapper\n",
      "    raise Conflict(message)\n",
      "telegram.error.Conflict: Conflict: terminated by other getUpdates request; make sure that only one bot instance is running\n",
      "Error while getting Updates: Conflict: terminated by other getUpdates request; make sure that only one bot instance is running\n",
      "No error handlers are registered, logging exception.\n",
      "Traceback (most recent call last):\n",
      "  File \"c:\\Users\\virtue\\anaconda3\\envs\\study\\lib\\site-packages\\telegram\\ext\\updater.py\", line 651, in _network_loop_retry\n",
      "    if not action_cb():\n",
      "  File \"c:\\Users\\virtue\\anaconda3\\envs\\study\\lib\\site-packages\\telegram\\ext\\updater.py\", line 602, in polling_action_cb\n",
      "    updates = self.bot.get_updates(\n",
      "  File \"c:\\Users\\virtue\\anaconda3\\envs\\study\\lib\\site-packages\\telegram\\ext\\extbot.py\", line 226, in get_updates\n",
      "    updates = super().get_updates(\n",
      "  File \"c:\\Users\\virtue\\anaconda3\\envs\\study\\lib\\site-packages\\telegram\\bot.py\", line 133, in decorator\n",
      "    result = func(*args, **kwargs)\n",
      "  File \"c:\\Users\\virtue\\anaconda3\\envs\\study\\lib\\site-packages\\telegram\\bot.py\", line 3057, in get_updates\n",
      "    self._post(\n",
      "  File \"c:\\Users\\virtue\\anaconda3\\envs\\study\\lib\\site-packages\\telegram\\bot.py\", line 298, in _post\n",
      "    return self.request.post(\n",
      "  File \"c:\\Users\\virtue\\anaconda3\\envs\\study\\lib\\site-packages\\telegram\\utils\\request.py\", line 361, in post\n",
      "    result = self._request_wrapper(\n",
      "  File \"c:\\Users\\virtue\\anaconda3\\envs\\study\\lib\\site-packages\\telegram\\utils\\request.py\", line 283, in _request_wrapper\n",
      "    raise Conflict(message)\n",
      "telegram.error.Conflict: Conflict: terminated by other getUpdates request; make sure that only one bot instance is running\n",
      "Error while getting Updates: Conflict: terminated by other getUpdates request; make sure that only one bot instance is running\n",
      "No error handlers are registered, logging exception.\n",
      "Traceback (most recent call last):\n",
      "  File \"c:\\Users\\virtue\\anaconda3\\envs\\study\\lib\\site-packages\\telegram\\ext\\updater.py\", line 651, in _network_loop_retry\n",
      "    if not action_cb():\n",
      "  File \"c:\\Users\\virtue\\anaconda3\\envs\\study\\lib\\site-packages\\telegram\\ext\\updater.py\", line 602, in polling_action_cb\n",
      "    updates = self.bot.get_updates(\n",
      "  File \"c:\\Users\\virtue\\anaconda3\\envs\\study\\lib\\site-packages\\telegram\\ext\\extbot.py\", line 226, in get_updates\n",
      "    updates = super().get_updates(\n",
      "  File \"c:\\Users\\virtue\\anaconda3\\envs\\study\\lib\\site-packages\\telegram\\bot.py\", line 133, in decorator\n",
      "    result = func(*args, **kwargs)\n",
      "  File \"c:\\Users\\virtue\\anaconda3\\envs\\study\\lib\\site-packages\\telegram\\bot.py\", line 3057, in get_updates\n",
      "    self._post(\n",
      "  File \"c:\\Users\\virtue\\anaconda3\\envs\\study\\lib\\site-packages\\telegram\\bot.py\", line 298, in _post\n",
      "    return self.request.post(\n",
      "  File \"c:\\Users\\virtue\\anaconda3\\envs\\study\\lib\\site-packages\\telegram\\utils\\request.py\", line 361, in post\n",
      "    result = self._request_wrapper(\n",
      "  File \"c:\\Users\\virtue\\anaconda3\\envs\\study\\lib\\site-packages\\telegram\\utils\\request.py\", line 283, in _request_wrapper\n",
      "    raise Conflict(message)\n",
      "telegram.error.Conflict: Conflict: terminated by other getUpdates request; make sure that only one bot instance is running\n",
      "Error while getting Updates: Conflict: terminated by other getUpdates request; make sure that only one bot instance is running\n",
      "No error handlers are registered, logging exception.\n",
      "Traceback (most recent call last):\n",
      "  File \"c:\\Users\\virtue\\anaconda3\\envs\\study\\lib\\site-packages\\telegram\\ext\\updater.py\", line 651, in _network_loop_retry\n",
      "    if not action_cb():\n",
      "  File \"c:\\Users\\virtue\\anaconda3\\envs\\study\\lib\\site-packages\\telegram\\ext\\updater.py\", line 602, in polling_action_cb\n",
      "    updates = self.bot.get_updates(\n",
      "  File \"c:\\Users\\virtue\\anaconda3\\envs\\study\\lib\\site-packages\\telegram\\ext\\extbot.py\", line 226, in get_updates\n",
      "    updates = super().get_updates(\n",
      "  File \"c:\\Users\\virtue\\anaconda3\\envs\\study\\lib\\site-packages\\telegram\\bot.py\", line 133, in decorator\n",
      "    result = func(*args, **kwargs)\n",
      "  File \"c:\\Users\\virtue\\anaconda3\\envs\\study\\lib\\site-packages\\telegram\\bot.py\", line 3057, in get_updates\n",
      "    self._post(\n",
      "  File \"c:\\Users\\virtue\\anaconda3\\envs\\study\\lib\\site-packages\\telegram\\bot.py\", line 298, in _post\n",
      "    return self.request.post(\n",
      "  File \"c:\\Users\\virtue\\anaconda3\\envs\\study\\lib\\site-packages\\telegram\\utils\\request.py\", line 361, in post\n",
      "    result = self._request_wrapper(\n",
      "  File \"c:\\Users\\virtue\\anaconda3\\envs\\study\\lib\\site-packages\\telegram\\utils\\request.py\", line 283, in _request_wrapper\n",
      "    raise Conflict(message)\n",
      "telegram.error.Conflict: Conflict: terminated by other getUpdates request; make sure that only one bot instance is running\n",
      "Error while getting Updates: Conflict: terminated by other getUpdates request; make sure that only one bot instance is running\n",
      "No error handlers are registered, logging exception.\n",
      "Traceback (most recent call last):\n",
      "  File \"c:\\Users\\virtue\\anaconda3\\envs\\study\\lib\\site-packages\\telegram\\ext\\updater.py\", line 651, in _network_loop_retry\n",
      "    if not action_cb():\n",
      "  File \"c:\\Users\\virtue\\anaconda3\\envs\\study\\lib\\site-packages\\telegram\\ext\\updater.py\", line 602, in polling_action_cb\n",
      "    updates = self.bot.get_updates(\n",
      "  File \"c:\\Users\\virtue\\anaconda3\\envs\\study\\lib\\site-packages\\telegram\\ext\\extbot.py\", line 226, in get_updates\n",
      "    updates = super().get_updates(\n",
      "  File \"c:\\Users\\virtue\\anaconda3\\envs\\study\\lib\\site-packages\\telegram\\bot.py\", line 133, in decorator\n",
      "    result = func(*args, **kwargs)\n",
      "  File \"c:\\Users\\virtue\\anaconda3\\envs\\study\\lib\\site-packages\\telegram\\bot.py\", line 3057, in get_updates\n",
      "    self._post(\n",
      "  File \"c:\\Users\\virtue\\anaconda3\\envs\\study\\lib\\site-packages\\telegram\\bot.py\", line 298, in _post\n",
      "    return self.request.post(\n",
      "  File \"c:\\Users\\virtue\\anaconda3\\envs\\study\\lib\\site-packages\\telegram\\utils\\request.py\", line 361, in post\n",
      "    result = self._request_wrapper(\n",
      "  File \"c:\\Users\\virtue\\anaconda3\\envs\\study\\lib\\site-packages\\telegram\\utils\\request.py\", line 283, in _request_wrapper\n",
      "    raise Conflict(message)\n",
      "telegram.error.Conflict: Conflict: terminated by other getUpdates request; make sure that only one bot instance is running\n",
      "Error while getting Updates: Conflict: terminated by other getUpdates request; make sure that only one bot instance is running\n",
      "No error handlers are registered, logging exception.\n",
      "Traceback (most recent call last):\n",
      "  File \"c:\\Users\\virtue\\anaconda3\\envs\\study\\lib\\site-packages\\telegram\\ext\\updater.py\", line 651, in _network_loop_retry\n",
      "    if not action_cb():\n",
      "  File \"c:\\Users\\virtue\\anaconda3\\envs\\study\\lib\\site-packages\\telegram\\ext\\updater.py\", line 602, in polling_action_cb\n",
      "    updates = self.bot.get_updates(\n",
      "  File \"c:\\Users\\virtue\\anaconda3\\envs\\study\\lib\\site-packages\\telegram\\ext\\extbot.py\", line 226, in get_updates\n",
      "    updates = super().get_updates(\n",
      "  File \"c:\\Users\\virtue\\anaconda3\\envs\\study\\lib\\site-packages\\telegram\\bot.py\", line 133, in decorator\n",
      "    result = func(*args, **kwargs)\n",
      "  File \"c:\\Users\\virtue\\anaconda3\\envs\\study\\lib\\site-packages\\telegram\\bot.py\", line 3057, in get_updates\n",
      "    self._post(\n",
      "  File \"c:\\Users\\virtue\\anaconda3\\envs\\study\\lib\\site-packages\\telegram\\bot.py\", line 298, in _post\n",
      "    return self.request.post(\n",
      "  File \"c:\\Users\\virtue\\anaconda3\\envs\\study\\lib\\site-packages\\telegram\\utils\\request.py\", line 361, in post\n",
      "    result = self._request_wrapper(\n",
      "  File \"c:\\Users\\virtue\\anaconda3\\envs\\study\\lib\\site-packages\\telegram\\utils\\request.py\", line 283, in _request_wrapper\n",
      "    raise Conflict(message)\n",
      "telegram.error.Conflict: Conflict: terminated by other getUpdates request; make sure that only one bot instance is running\n",
      "Error while getting Updates: Conflict: terminated by other getUpdates request; make sure that only one bot instance is running\n",
      "No error handlers are registered, logging exception.\n",
      "Traceback (most recent call last):\n",
      "  File \"c:\\Users\\virtue\\anaconda3\\envs\\study\\lib\\site-packages\\telegram\\ext\\updater.py\", line 651, in _network_loop_retry\n",
      "    if not action_cb():\n",
      "  File \"c:\\Users\\virtue\\anaconda3\\envs\\study\\lib\\site-packages\\telegram\\ext\\updater.py\", line 602, in polling_action_cb\n",
      "    updates = self.bot.get_updates(\n",
      "  File \"c:\\Users\\virtue\\anaconda3\\envs\\study\\lib\\site-packages\\telegram\\ext\\extbot.py\", line 226, in get_updates\n",
      "    updates = super().get_updates(\n",
      "  File \"c:\\Users\\virtue\\anaconda3\\envs\\study\\lib\\site-packages\\telegram\\bot.py\", line 133, in decorator\n",
      "    result = func(*args, **kwargs)\n",
      "  File \"c:\\Users\\virtue\\anaconda3\\envs\\study\\lib\\site-packages\\telegram\\bot.py\", line 3057, in get_updates\n",
      "    self._post(\n",
      "  File \"c:\\Users\\virtue\\anaconda3\\envs\\study\\lib\\site-packages\\telegram\\bot.py\", line 298, in _post\n",
      "    return self.request.post(\n",
      "  File \"c:\\Users\\virtue\\anaconda3\\envs\\study\\lib\\site-packages\\telegram\\utils\\request.py\", line 361, in post\n",
      "    result = self._request_wrapper(\n",
      "  File \"c:\\Users\\virtue\\anaconda3\\envs\\study\\lib\\site-packages\\telegram\\utils\\request.py\", line 283, in _request_wrapper\n",
      "    raise Conflict(message)\n",
      "telegram.error.Conflict: Conflict: terminated by other getUpdates request; make sure that only one bot instance is running\n",
      "Error while getting Updates: Conflict: terminated by other getUpdates request; make sure that only one bot instance is running\n",
      "No error handlers are registered, logging exception.\n",
      "Traceback (most recent call last):\n",
      "  File \"c:\\Users\\virtue\\anaconda3\\envs\\study\\lib\\site-packages\\telegram\\ext\\updater.py\", line 651, in _network_loop_retry\n",
      "    if not action_cb():\n",
      "  File \"c:\\Users\\virtue\\anaconda3\\envs\\study\\lib\\site-packages\\telegram\\ext\\updater.py\", line 602, in polling_action_cb\n",
      "    updates = self.bot.get_updates(\n",
      "  File \"c:\\Users\\virtue\\anaconda3\\envs\\study\\lib\\site-packages\\telegram\\ext\\extbot.py\", line 226, in get_updates\n",
      "    updates = super().get_updates(\n",
      "  File \"c:\\Users\\virtue\\anaconda3\\envs\\study\\lib\\site-packages\\telegram\\bot.py\", line 133, in decorator\n",
      "    result = func(*args, **kwargs)\n",
      "  File \"c:\\Users\\virtue\\anaconda3\\envs\\study\\lib\\site-packages\\telegram\\bot.py\", line 3057, in get_updates\n",
      "    self._post(\n",
      "  File \"c:\\Users\\virtue\\anaconda3\\envs\\study\\lib\\site-packages\\telegram\\bot.py\", line 298, in _post\n",
      "    return self.request.post(\n",
      "  File \"c:\\Users\\virtue\\anaconda3\\envs\\study\\lib\\site-packages\\telegram\\utils\\request.py\", line 361, in post\n",
      "    result = self._request_wrapper(\n",
      "  File \"c:\\Users\\virtue\\anaconda3\\envs\\study\\lib\\site-packages\\telegram\\utils\\request.py\", line 283, in _request_wrapper\n",
      "    raise Conflict(message)\n",
      "telegram.error.Conflict: Conflict: terminated by other getUpdates request; make sure that only one bot instance is running\n",
      "Error while getting Updates: Conflict: terminated by other getUpdates request; make sure that only one bot instance is running\n",
      "No error handlers are registered, logging exception.\n",
      "Traceback (most recent call last):\n",
      "  File \"c:\\Users\\virtue\\anaconda3\\envs\\study\\lib\\site-packages\\telegram\\ext\\updater.py\", line 651, in _network_loop_retry\n",
      "    if not action_cb():\n",
      "  File \"c:\\Users\\virtue\\anaconda3\\envs\\study\\lib\\site-packages\\telegram\\ext\\updater.py\", line 602, in polling_action_cb\n",
      "    updates = self.bot.get_updates(\n",
      "  File \"c:\\Users\\virtue\\anaconda3\\envs\\study\\lib\\site-packages\\telegram\\ext\\extbot.py\", line 226, in get_updates\n",
      "    updates = super().get_updates(\n",
      "  File \"c:\\Users\\virtue\\anaconda3\\envs\\study\\lib\\site-packages\\telegram\\bot.py\", line 133, in decorator\n",
      "    result = func(*args, **kwargs)\n",
      "  File \"c:\\Users\\virtue\\anaconda3\\envs\\study\\lib\\site-packages\\telegram\\bot.py\", line 3057, in get_updates\n",
      "    self._post(\n",
      "  File \"c:\\Users\\virtue\\anaconda3\\envs\\study\\lib\\site-packages\\telegram\\bot.py\", line 298, in _post\n",
      "    return self.request.post(\n",
      "  File \"c:\\Users\\virtue\\anaconda3\\envs\\study\\lib\\site-packages\\telegram\\utils\\request.py\", line 361, in post\n",
      "    result = self._request_wrapper(\n",
      "  File \"c:\\Users\\virtue\\anaconda3\\envs\\study\\lib\\site-packages\\telegram\\utils\\request.py\", line 283, in _request_wrapper\n",
      "    raise Conflict(message)\n",
      "telegram.error.Conflict: Conflict: terminated by other getUpdates request; make sure that only one bot instance is running\n",
      "No error handlers are registered, logging exception.\n",
      "Traceback (most recent call last):\n",
      "  File \"c:\\Users\\virtue\\anaconda3\\envs\\study\\lib\\site-packages\\telegram\\ext\\dispatcher.py\", line 557, in process_update\n",
      "    handler.handle_update(update, self, check, context)\n",
      "  File \"c:\\Users\\virtue\\anaconda3\\envs\\study\\lib\\site-packages\\telegram\\ext\\handler.py\", line 199, in handle_update\n",
      "    return self.callback(update, context)\n",
      "  File \"C:\\Users\\virtue\\AppData\\Local\\Temp\\ipykernel_16040\\3014515975.py\", line 26, in handler\n",
      "    data = naver_crawling()\n",
      "  File \"C:\\Users\\virtue\\AppData\\Local\\Temp\\ipykernel_16040\\3681364787.py\", line 38, in naver_crawling\n",
      "    final_result='원어명: '+ spain_result['원어명'] + '위치: '+ spain_result['위치']+ '시간대: '+spain_result['시간대'] +'면적(㎢): '+ spain_result['면적(㎢)']+'시간대: '+spain_result['시간대']+'수도: '+spain_result['수도']+'종족구성: '+spain_result['종족구성']+'국제전화: '+spain_result['국제전화']\n",
      "KeyError: '위치'\n",
      "Error while getting Updates: Conflict: terminated by other getUpdates request; make sure that only one bot instance is running\n",
      "No error handlers are registered, logging exception.\n",
      "Traceback (most recent call last):\n",
      "  File \"c:\\Users\\virtue\\anaconda3\\envs\\study\\lib\\site-packages\\telegram\\ext\\updater.py\", line 651, in _network_loop_retry\n",
      "    if not action_cb():\n",
      "  File \"c:\\Users\\virtue\\anaconda3\\envs\\study\\lib\\site-packages\\telegram\\ext\\updater.py\", line 602, in polling_action_cb\n",
      "    updates = self.bot.get_updates(\n",
      "  File \"c:\\Users\\virtue\\anaconda3\\envs\\study\\lib\\site-packages\\telegram\\ext\\extbot.py\", line 226, in get_updates\n",
      "    updates = super().get_updates(\n",
      "  File \"c:\\Users\\virtue\\anaconda3\\envs\\study\\lib\\site-packages\\telegram\\bot.py\", line 133, in decorator\n",
      "    result = func(*args, **kwargs)\n",
      "  File \"c:\\Users\\virtue\\anaconda3\\envs\\study\\lib\\site-packages\\telegram\\bot.py\", line 3057, in get_updates\n",
      "    self._post(\n",
      "  File \"c:\\Users\\virtue\\anaconda3\\envs\\study\\lib\\site-packages\\telegram\\bot.py\", line 298, in _post\n",
      "    return self.request.post(\n",
      "  File \"c:\\Users\\virtue\\anaconda3\\envs\\study\\lib\\site-packages\\telegram\\utils\\request.py\", line 361, in post\n",
      "    result = self._request_wrapper(\n",
      "  File \"c:\\Users\\virtue\\anaconda3\\envs\\study\\lib\\site-packages\\telegram\\utils\\request.py\", line 283, in _request_wrapper\n",
      "    raise Conflict(message)\n",
      "telegram.error.Conflict: Conflict: terminated by other getUpdates request; make sure that only one bot instance is running\n",
      "Error while getting Updates: Conflict: terminated by other getUpdates request; make sure that only one bot instance is running\n",
      "Error while getting Updates: Conflict: terminated by other getUpdates request; make sure that only one bot instance is running\n",
      "No error handlers are registered, logging exception.\n",
      "Traceback (most recent call last):\n",
      "  File \"c:\\Users\\virtue\\anaconda3\\envs\\study\\lib\\site-packages\\telegram\\ext\\updater.py\", line 651, in _network_loop_retry\n",
      "    if not action_cb():\n",
      "  File \"c:\\Users\\virtue\\anaconda3\\envs\\study\\lib\\site-packages\\telegram\\ext\\updater.py\", line 602, in polling_action_cb\n",
      "    updates = self.bot.get_updates(\n",
      "  File \"c:\\Users\\virtue\\anaconda3\\envs\\study\\lib\\site-packages\\telegram\\ext\\extbot.py\", line 226, in get_updates\n",
      "    updates = super().get_updates(\n",
      "  File \"c:\\Users\\virtue\\anaconda3\\envs\\study\\lib\\site-packages\\telegram\\bot.py\", line 133, in decorator\n",
      "    result = func(*args, **kwargs)\n",
      "  File \"c:\\Users\\virtue\\anaconda3\\envs\\study\\lib\\site-packages\\telegram\\bot.py\", line 3057, in get_updates\n",
      "    self._post(\n",
      "  File \"c:\\Users\\virtue\\anaconda3\\envs\\study\\lib\\site-packages\\telegram\\bot.py\", line 298, in _post\n",
      "    return self.request.post(\n",
      "  File \"c:\\Users\\virtue\\anaconda3\\envs\\study\\lib\\site-packages\\telegram\\utils\\request.py\", line 361, in post\n",
      "    result = self._request_wrapper(\n",
      "  File \"c:\\Users\\virtue\\anaconda3\\envs\\study\\lib\\site-packages\\telegram\\utils\\request.py\", line 283, in _request_wrapper\n",
      "    raise Conflict(message)\n",
      "telegram.error.Conflict: Conflict: terminated by other getUpdates request; make sure that only one bot instance is running\n",
      "No error handlers are registered, logging exception.\n",
      "Traceback (most recent call last):\n",
      "  File \"c:\\Users\\virtue\\anaconda3\\envs\\study\\lib\\site-packages\\telegram\\ext\\updater.py\", line 651, in _network_loop_retry\n",
      "    if not action_cb():\n",
      "  File \"c:\\Users\\virtue\\anaconda3\\envs\\study\\lib\\site-packages\\telegram\\ext\\updater.py\", line 602, in polling_action_cb\n",
      "    updates = self.bot.get_updates(\n",
      "  File \"c:\\Users\\virtue\\anaconda3\\envs\\study\\lib\\site-packages\\telegram\\ext\\extbot.py\", line 226, in get_updates\n",
      "    updates = super().get_updates(\n",
      "  File \"c:\\Users\\virtue\\anaconda3\\envs\\study\\lib\\site-packages\\telegram\\bot.py\", line 133, in decorator\n",
      "    result = func(*args, **kwargs)\n",
      "  File \"c:\\Users\\virtue\\anaconda3\\envs\\study\\lib\\site-packages\\telegram\\bot.py\", line 3057, in get_updates\n",
      "    self._post(\n",
      "  File \"c:\\Users\\virtue\\anaconda3\\envs\\study\\lib\\site-packages\\telegram\\bot.py\", line 298, in _post\n",
      "    return self.request.post(\n",
      "  File \"c:\\Users\\virtue\\anaconda3\\envs\\study\\lib\\site-packages\\telegram\\utils\\request.py\", line 361, in post\n",
      "    result = self._request_wrapper(\n",
      "  File \"c:\\Users\\virtue\\anaconda3\\envs\\study\\lib\\site-packages\\telegram\\utils\\request.py\", line 283, in _request_wrapper\n",
      "    raise Conflict(message)\n",
      "telegram.error.Conflict: Conflict: terminated by other getUpdates request; make sure that only one bot instance is running\n",
      "Error while getting Updates: Conflict: terminated by other getUpdates request; make sure that only one bot instance is running\n",
      "No error handlers are registered, logging exception.\n",
      "Traceback (most recent call last):\n",
      "  File \"c:\\Users\\virtue\\anaconda3\\envs\\study\\lib\\site-packages\\telegram\\ext\\updater.py\", line 651, in _network_loop_retry\n",
      "    if not action_cb():\n",
      "  File \"c:\\Users\\virtue\\anaconda3\\envs\\study\\lib\\site-packages\\telegram\\ext\\updater.py\", line 602, in polling_action_cb\n",
      "    updates = self.bot.get_updates(\n",
      "  File \"c:\\Users\\virtue\\anaconda3\\envs\\study\\lib\\site-packages\\telegram\\ext\\extbot.py\", line 226, in get_updates\n",
      "    updates = super().get_updates(\n",
      "  File \"c:\\Users\\virtue\\anaconda3\\envs\\study\\lib\\site-packages\\telegram\\bot.py\", line 133, in decorator\n",
      "    result = func(*args, **kwargs)\n",
      "  File \"c:\\Users\\virtue\\anaconda3\\envs\\study\\lib\\site-packages\\telegram\\bot.py\", line 3057, in get_updates\n",
      "    self._post(\n",
      "  File \"c:\\Users\\virtue\\anaconda3\\envs\\study\\lib\\site-packages\\telegram\\bot.py\", line 298, in _post\n",
      "    return self.request.post(\n",
      "  File \"c:\\Users\\virtue\\anaconda3\\envs\\study\\lib\\site-packages\\telegram\\utils\\request.py\", line 361, in post\n",
      "    result = self._request_wrapper(\n",
      "  File \"c:\\Users\\virtue\\anaconda3\\envs\\study\\lib\\site-packages\\telegram\\utils\\request.py\", line 283, in _request_wrapper\n",
      "    raise Conflict(message)\n",
      "telegram.error.Conflict: Conflict: terminated by other getUpdates request; make sure that only one bot instance is running\n",
      "Error while getting Updates: Conflict: terminated by other getUpdates request; make sure that only one bot instance is running\n",
      "No error handlers are registered, logging exception.\n",
      "Traceback (most recent call last):\n",
      "  File \"c:\\Users\\virtue\\anaconda3\\envs\\study\\lib\\site-packages\\telegram\\ext\\updater.py\", line 651, in _network_loop_retry\n",
      "    if not action_cb():\n",
      "  File \"c:\\Users\\virtue\\anaconda3\\envs\\study\\lib\\site-packages\\telegram\\ext\\updater.py\", line 602, in polling_action_cb\n",
      "    updates = self.bot.get_updates(\n",
      "  File \"c:\\Users\\virtue\\anaconda3\\envs\\study\\lib\\site-packages\\telegram\\ext\\extbot.py\", line 226, in get_updates\n",
      "    updates = super().get_updates(\n",
      "  File \"c:\\Users\\virtue\\anaconda3\\envs\\study\\lib\\site-packages\\telegram\\bot.py\", line 133, in decorator\n",
      "    result = func(*args, **kwargs)\n",
      "  File \"c:\\Users\\virtue\\anaconda3\\envs\\study\\lib\\site-packages\\telegram\\bot.py\", line 3057, in get_updates\n",
      "    self._post(\n",
      "  File \"c:\\Users\\virtue\\anaconda3\\envs\\study\\lib\\site-packages\\telegram\\bot.py\", line 298, in _post\n",
      "    return self.request.post(\n",
      "  File \"c:\\Users\\virtue\\anaconda3\\envs\\study\\lib\\site-packages\\telegram\\utils\\request.py\", line 361, in post\n",
      "    result = self._request_wrapper(\n",
      "  File \"c:\\Users\\virtue\\anaconda3\\envs\\study\\lib\\site-packages\\telegram\\utils\\request.py\", line 283, in _request_wrapper\n",
      "    raise Conflict(message)\n",
      "telegram.error.Conflict: Conflict: terminated by other getUpdates request; make sure that only one bot instance is running\n",
      "Error while getting Updates: Conflict: terminated by other getUpdates request; make sure that only one bot instance is running\n",
      "No error handlers are registered, logging exception.\n",
      "Traceback (most recent call last):\n",
      "  File \"c:\\Users\\virtue\\anaconda3\\envs\\study\\lib\\site-packages\\telegram\\ext\\updater.py\", line 651, in _network_loop_retry\n",
      "    if not action_cb():\n",
      "  File \"c:\\Users\\virtue\\anaconda3\\envs\\study\\lib\\site-packages\\telegram\\ext\\updater.py\", line 602, in polling_action_cb\n",
      "    updates = self.bot.get_updates(\n",
      "  File \"c:\\Users\\virtue\\anaconda3\\envs\\study\\lib\\site-packages\\telegram\\ext\\extbot.py\", line 226, in get_updates\n",
      "    updates = super().get_updates(\n",
      "  File \"c:\\Users\\virtue\\anaconda3\\envs\\study\\lib\\site-packages\\telegram\\bot.py\", line 133, in decorator\n",
      "    result = func(*args, **kwargs)\n",
      "  File \"c:\\Users\\virtue\\anaconda3\\envs\\study\\lib\\site-packages\\telegram\\bot.py\", line 3057, in get_updates\n",
      "    self._post(\n",
      "  File \"c:\\Users\\virtue\\anaconda3\\envs\\study\\lib\\site-packages\\telegram\\bot.py\", line 298, in _post\n",
      "    return self.request.post(\n",
      "  File \"c:\\Users\\virtue\\anaconda3\\envs\\study\\lib\\site-packages\\telegram\\utils\\request.py\", line 361, in post\n",
      "    result = self._request_wrapper(\n",
      "  File \"c:\\Users\\virtue\\anaconda3\\envs\\study\\lib\\site-packages\\telegram\\utils\\request.py\", line 283, in _request_wrapper\n",
      "    raise Conflict(message)\n",
      "telegram.error.Conflict: Conflict: terminated by other getUpdates request; make sure that only one bot instance is running\n",
      "Error while getting Updates: Conflict: terminated by other getUpdates request; make sure that only one bot instance is running\n",
      "No error handlers are registered, logging exception.\n",
      "Traceback (most recent call last):\n",
      "  File \"c:\\Users\\virtue\\anaconda3\\envs\\study\\lib\\site-packages\\telegram\\ext\\updater.py\", line 651, in _network_loop_retry\n",
      "    if not action_cb():\n",
      "  File \"c:\\Users\\virtue\\anaconda3\\envs\\study\\lib\\site-packages\\telegram\\ext\\updater.py\", line 602, in polling_action_cb\n",
      "    updates = self.bot.get_updates(\n",
      "  File \"c:\\Users\\virtue\\anaconda3\\envs\\study\\lib\\site-packages\\telegram\\ext\\extbot.py\", line 226, in get_updates\n",
      "    updates = super().get_updates(\n",
      "  File \"c:\\Users\\virtue\\anaconda3\\envs\\study\\lib\\site-packages\\telegram\\bot.py\", line 133, in decorator\n",
      "    result = func(*args, **kwargs)\n",
      "  File \"c:\\Users\\virtue\\anaconda3\\envs\\study\\lib\\site-packages\\telegram\\bot.py\", line 3057, in get_updates\n",
      "    self._post(\n",
      "  File \"c:\\Users\\virtue\\anaconda3\\envs\\study\\lib\\site-packages\\telegram\\bot.py\", line 298, in _post\n",
      "    return self.request.post(\n",
      "  File \"c:\\Users\\virtue\\anaconda3\\envs\\study\\lib\\site-packages\\telegram\\utils\\request.py\", line 361, in post\n",
      "    result = self._request_wrapper(\n",
      "  File \"c:\\Users\\virtue\\anaconda3\\envs\\study\\lib\\site-packages\\telegram\\utils\\request.py\", line 283, in _request_wrapper\n",
      "    raise Conflict(message)\n",
      "telegram.error.Conflict: Conflict: terminated by other getUpdates request; make sure that only one bot instance is running\n",
      "Error while getting Updates: Conflict: terminated by other getUpdates request; make sure that only one bot instance is running\n",
      "No error handlers are registered, logging exception.\n",
      "Traceback (most recent call last):\n",
      "  File \"c:\\Users\\virtue\\anaconda3\\envs\\study\\lib\\site-packages\\telegram\\ext\\updater.py\", line 651, in _network_loop_retry\n",
      "    if not action_cb():\n",
      "  File \"c:\\Users\\virtue\\anaconda3\\envs\\study\\lib\\site-packages\\telegram\\ext\\updater.py\", line 602, in polling_action_cb\n",
      "    updates = self.bot.get_updates(\n",
      "  File \"c:\\Users\\virtue\\anaconda3\\envs\\study\\lib\\site-packages\\telegram\\ext\\extbot.py\", line 226, in get_updates\n",
      "    updates = super().get_updates(\n",
      "  File \"c:\\Users\\virtue\\anaconda3\\envs\\study\\lib\\site-packages\\telegram\\bot.py\", line 133, in decorator\n",
      "    result = func(*args, **kwargs)\n",
      "  File \"c:\\Users\\virtue\\anaconda3\\envs\\study\\lib\\site-packages\\telegram\\bot.py\", line 3057, in get_updates\n",
      "    self._post(\n",
      "  File \"c:\\Users\\virtue\\anaconda3\\envs\\study\\lib\\site-packages\\telegram\\bot.py\", line 298, in _post\n",
      "    return self.request.post(\n",
      "  File \"c:\\Users\\virtue\\anaconda3\\envs\\study\\lib\\site-packages\\telegram\\utils\\request.py\", line 361, in post\n",
      "    result = self._request_wrapper(\n",
      "  File \"c:\\Users\\virtue\\anaconda3\\envs\\study\\lib\\site-packages\\telegram\\utils\\request.py\", line 283, in _request_wrapper\n",
      "    raise Conflict(message)\n",
      "telegram.error.Conflict: Conflict: terminated by other getUpdates request; make sure that only one bot instance is running\n",
      "Error while getting Updates: Conflict: terminated by other getUpdates request; make sure that only one bot instance is running\n",
      "No error handlers are registered, logging exception.\n",
      "Traceback (most recent call last):\n",
      "  File \"c:\\Users\\virtue\\anaconda3\\envs\\study\\lib\\site-packages\\telegram\\ext\\updater.py\", line 651, in _network_loop_retry\n",
      "    if not action_cb():\n",
      "  File \"c:\\Users\\virtue\\anaconda3\\envs\\study\\lib\\site-packages\\telegram\\ext\\updater.py\", line 602, in polling_action_cb\n",
      "    updates = self.bot.get_updates(\n",
      "  File \"c:\\Users\\virtue\\anaconda3\\envs\\study\\lib\\site-packages\\telegram\\ext\\extbot.py\", line 226, in get_updates\n",
      "    updates = super().get_updates(\n",
      "  File \"c:\\Users\\virtue\\anaconda3\\envs\\study\\lib\\site-packages\\telegram\\bot.py\", line 133, in decorator\n",
      "    result = func(*args, **kwargs)\n",
      "  File \"c:\\Users\\virtue\\anaconda3\\envs\\study\\lib\\site-packages\\telegram\\bot.py\", line 3057, in get_updates\n",
      "    self._post(\n",
      "  File \"c:\\Users\\virtue\\anaconda3\\envs\\study\\lib\\site-packages\\telegram\\bot.py\", line 298, in _post\n",
      "    return self.request.post(\n",
      "  File \"c:\\Users\\virtue\\anaconda3\\envs\\study\\lib\\site-packages\\telegram\\utils\\request.py\", line 361, in post\n",
      "    result = self._request_wrapper(\n",
      "  File \"c:\\Users\\virtue\\anaconda3\\envs\\study\\lib\\site-packages\\telegram\\utils\\request.py\", line 283, in _request_wrapper\n",
      "    raise Conflict(message)\n",
      "telegram.error.Conflict: Conflict: terminated by other getUpdates request; make sure that only one bot instance is running\n",
      "Error while getting Updates: Conflict: terminated by other getUpdates request; make sure that only one bot instance is running\n",
      "No error handlers are registered, logging exception.\n",
      "Traceback (most recent call last):\n",
      "  File \"c:\\Users\\virtue\\anaconda3\\envs\\study\\lib\\site-packages\\telegram\\ext\\updater.py\", line 651, in _network_loop_retry\n",
      "    if not action_cb():\n",
      "  File \"c:\\Users\\virtue\\anaconda3\\envs\\study\\lib\\site-packages\\telegram\\ext\\updater.py\", line 602, in polling_action_cb\n",
      "    updates = self.bot.get_updates(\n",
      "  File \"c:\\Users\\virtue\\anaconda3\\envs\\study\\lib\\site-packages\\telegram\\ext\\extbot.py\", line 226, in get_updates\n",
      "    updates = super().get_updates(\n",
      "  File \"c:\\Users\\virtue\\anaconda3\\envs\\study\\lib\\site-packages\\telegram\\bot.py\", line 133, in decorator\n",
      "    result = func(*args, **kwargs)\n",
      "  File \"c:\\Users\\virtue\\anaconda3\\envs\\study\\lib\\site-packages\\telegram\\bot.py\", line 3057, in get_updates\n",
      "    self._post(\n",
      "  File \"c:\\Users\\virtue\\anaconda3\\envs\\study\\lib\\site-packages\\telegram\\bot.py\", line 298, in _post\n",
      "    return self.request.post(\n",
      "  File \"c:\\Users\\virtue\\anaconda3\\envs\\study\\lib\\site-packages\\telegram\\utils\\request.py\", line 361, in post\n",
      "    result = self._request_wrapper(\n",
      "  File \"c:\\Users\\virtue\\anaconda3\\envs\\study\\lib\\site-packages\\telegram\\utils\\request.py\", line 283, in _request_wrapper\n",
      "    raise Conflict(message)\n",
      "telegram.error.Conflict: Conflict: terminated by other getUpdates request; make sure that only one bot instance is running\n",
      "Error while getting Updates: Conflict: terminated by other getUpdates request; make sure that only one bot instance is running\n",
      "No error handlers are registered, logging exception.\n",
      "Traceback (most recent call last):\n",
      "  File \"c:\\Users\\virtue\\anaconda3\\envs\\study\\lib\\site-packages\\telegram\\ext\\updater.py\", line 651, in _network_loop_retry\n",
      "    if not action_cb():\n",
      "  File \"c:\\Users\\virtue\\anaconda3\\envs\\study\\lib\\site-packages\\telegram\\ext\\updater.py\", line 602, in polling_action_cb\n",
      "    updates = self.bot.get_updates(\n",
      "  File \"c:\\Users\\virtue\\anaconda3\\envs\\study\\lib\\site-packages\\telegram\\ext\\extbot.py\", line 226, in get_updates\n",
      "    updates = super().get_updates(\n",
      "  File \"c:\\Users\\virtue\\anaconda3\\envs\\study\\lib\\site-packages\\telegram\\bot.py\", line 133, in decorator\n",
      "    result = func(*args, **kwargs)\n",
      "  File \"c:\\Users\\virtue\\anaconda3\\envs\\study\\lib\\site-packages\\telegram\\bot.py\", line 3057, in get_updates\n",
      "    self._post(\n",
      "  File \"c:\\Users\\virtue\\anaconda3\\envs\\study\\lib\\site-packages\\telegram\\bot.py\", line 298, in _post\n",
      "    return self.request.post(\n",
      "  File \"c:\\Users\\virtue\\anaconda3\\envs\\study\\lib\\site-packages\\telegram\\utils\\request.py\", line 361, in post\n",
      "    result = self._request_wrapper(\n",
      "  File \"c:\\Users\\virtue\\anaconda3\\envs\\study\\lib\\site-packages\\telegram\\utils\\request.py\", line 283, in _request_wrapper\n",
      "    raise Conflict(message)\n",
      "telegram.error.Conflict: Conflict: terminated by other getUpdates request; make sure that only one bot instance is running\n",
      "Error while getting Updates: Conflict: terminated by other getUpdates request; make sure that only one bot instance is running\n",
      "No error handlers are registered, logging exception.\n",
      "Traceback (most recent call last):\n",
      "  File \"c:\\Users\\virtue\\anaconda3\\envs\\study\\lib\\site-packages\\telegram\\ext\\updater.py\", line 651, in _network_loop_retry\n",
      "    if not action_cb():\n",
      "  File \"c:\\Users\\virtue\\anaconda3\\envs\\study\\lib\\site-packages\\telegram\\ext\\updater.py\", line 602, in polling_action_cb\n",
      "    updates = self.bot.get_updates(\n",
      "  File \"c:\\Users\\virtue\\anaconda3\\envs\\study\\lib\\site-packages\\telegram\\ext\\extbot.py\", line 226, in get_updates\n",
      "    updates = super().get_updates(\n",
      "  File \"c:\\Users\\virtue\\anaconda3\\envs\\study\\lib\\site-packages\\telegram\\bot.py\", line 133, in decorator\n",
      "    result = func(*args, **kwargs)\n",
      "  File \"c:\\Users\\virtue\\anaconda3\\envs\\study\\lib\\site-packages\\telegram\\bot.py\", line 3057, in get_updates\n",
      "    self._post(\n",
      "  File \"c:\\Users\\virtue\\anaconda3\\envs\\study\\lib\\site-packages\\telegram\\bot.py\", line 298, in _post\n",
      "    return self.request.post(\n",
      "  File \"c:\\Users\\virtue\\anaconda3\\envs\\study\\lib\\site-packages\\telegram\\utils\\request.py\", line 361, in post\n",
      "    result = self._request_wrapper(\n",
      "  File \"c:\\Users\\virtue\\anaconda3\\envs\\study\\lib\\site-packages\\telegram\\utils\\request.py\", line 283, in _request_wrapper\n",
      "    raise Conflict(message)\n",
      "telegram.error.Conflict: Conflict: terminated by other getUpdates request; make sure that only one bot instance is running\n",
      "Error while getting Updates: Conflict: terminated by other getUpdates request; make sure that only one bot instance is running\n",
      "No error handlers are registered, logging exception.\n",
      "Traceback (most recent call last):\n",
      "  File \"c:\\Users\\virtue\\anaconda3\\envs\\study\\lib\\site-packages\\telegram\\ext\\updater.py\", line 651, in _network_loop_retry\n",
      "    if not action_cb():\n",
      "  File \"c:\\Users\\virtue\\anaconda3\\envs\\study\\lib\\site-packages\\telegram\\ext\\updater.py\", line 602, in polling_action_cb\n",
      "    updates = self.bot.get_updates(\n",
      "  File \"c:\\Users\\virtue\\anaconda3\\envs\\study\\lib\\site-packages\\telegram\\ext\\extbot.py\", line 226, in get_updates\n",
      "    updates = super().get_updates(\n",
      "  File \"c:\\Users\\virtue\\anaconda3\\envs\\study\\lib\\site-packages\\telegram\\bot.py\", line 133, in decorator\n",
      "    result = func(*args, **kwargs)\n",
      "  File \"c:\\Users\\virtue\\anaconda3\\envs\\study\\lib\\site-packages\\telegram\\bot.py\", line 3057, in get_updates\n",
      "    self._post(\n",
      "  File \"c:\\Users\\virtue\\anaconda3\\envs\\study\\lib\\site-packages\\telegram\\bot.py\", line 298, in _post\n",
      "    return self.request.post(\n",
      "  File \"c:\\Users\\virtue\\anaconda3\\envs\\study\\lib\\site-packages\\telegram\\utils\\request.py\", line 361, in post\n",
      "    result = self._request_wrapper(\n",
      "  File \"c:\\Users\\virtue\\anaconda3\\envs\\study\\lib\\site-packages\\telegram\\utils\\request.py\", line 283, in _request_wrapper\n",
      "    raise Conflict(message)\n",
      "telegram.error.Conflict: Conflict: terminated by other getUpdates request; make sure that only one bot instance is running\n",
      "Error while getting Updates: Conflict: terminated by other getUpdates request; make sure that only one bot instance is running\n",
      "No error handlers are registered, logging exception.\n",
      "Traceback (most recent call last):\n",
      "  File \"c:\\Users\\virtue\\anaconda3\\envs\\study\\lib\\site-packages\\telegram\\ext\\updater.py\", line 651, in _network_loop_retry\n",
      "    if not action_cb():\n",
      "  File \"c:\\Users\\virtue\\anaconda3\\envs\\study\\lib\\site-packages\\telegram\\ext\\updater.py\", line 602, in polling_action_cb\n",
      "    updates = self.bot.get_updates(\n",
      "  File \"c:\\Users\\virtue\\anaconda3\\envs\\study\\lib\\site-packages\\telegram\\ext\\extbot.py\", line 226, in get_updates\n",
      "    updates = super().get_updates(\n",
      "  File \"c:\\Users\\virtue\\anaconda3\\envs\\study\\lib\\site-packages\\telegram\\bot.py\", line 133, in decorator\n",
      "    result = func(*args, **kwargs)\n",
      "  File \"c:\\Users\\virtue\\anaconda3\\envs\\study\\lib\\site-packages\\telegram\\bot.py\", line 3057, in get_updates\n",
      "    self._post(\n",
      "  File \"c:\\Users\\virtue\\anaconda3\\envs\\study\\lib\\site-packages\\telegram\\bot.py\", line 298, in _post\n",
      "    return self.request.post(\n",
      "  File \"c:\\Users\\virtue\\anaconda3\\envs\\study\\lib\\site-packages\\telegram\\utils\\request.py\", line 361, in post\n",
      "    result = self._request_wrapper(\n",
      "  File \"c:\\Users\\virtue\\anaconda3\\envs\\study\\lib\\site-packages\\telegram\\utils\\request.py\", line 283, in _request_wrapper\n",
      "    raise Conflict(message)\n",
      "telegram.error.Conflict: Conflict: terminated by other getUpdates request; make sure that only one bot instance is running\n",
      "Error while getting Updates: Conflict: terminated by other getUpdates request; make sure that only one bot instance is running\n",
      "No error handlers are registered, logging exception.\n",
      "Traceback (most recent call last):\n",
      "  File \"c:\\Users\\virtue\\anaconda3\\envs\\study\\lib\\site-packages\\telegram\\ext\\updater.py\", line 651, in _network_loop_retry\n",
      "    if not action_cb():\n",
      "  File \"c:\\Users\\virtue\\anaconda3\\envs\\study\\lib\\site-packages\\telegram\\ext\\updater.py\", line 602, in polling_action_cb\n",
      "    updates = self.bot.get_updates(\n",
      "  File \"c:\\Users\\virtue\\anaconda3\\envs\\study\\lib\\site-packages\\telegram\\ext\\extbot.py\", line 226, in get_updates\n",
      "    updates = super().get_updates(\n",
      "  File \"c:\\Users\\virtue\\anaconda3\\envs\\study\\lib\\site-packages\\telegram\\bot.py\", line 133, in decorator\n",
      "    result = func(*args, **kwargs)\n",
      "  File \"c:\\Users\\virtue\\anaconda3\\envs\\study\\lib\\site-packages\\telegram\\bot.py\", line 3057, in get_updates\n",
      "    self._post(\n",
      "  File \"c:\\Users\\virtue\\anaconda3\\envs\\study\\lib\\site-packages\\telegram\\bot.py\", line 298, in _post\n",
      "    return self.request.post(\n",
      "  File \"c:\\Users\\virtue\\anaconda3\\envs\\study\\lib\\site-packages\\telegram\\utils\\request.py\", line 361, in post\n",
      "    result = self._request_wrapper(\n",
      "  File \"c:\\Users\\virtue\\anaconda3\\envs\\study\\lib\\site-packages\\telegram\\utils\\request.py\", line 283, in _request_wrapper\n",
      "    raise Conflict(message)\n",
      "telegram.error.Conflict: Conflict: terminated by other getUpdates request; make sure that only one bot instance is running\n",
      "Error while getting Updates: Conflict: terminated by other getUpdates request; make sure that only one bot instance is running\n",
      "No error handlers are registered, logging exception.\n",
      "Traceback (most recent call last):\n",
      "  File \"c:\\Users\\virtue\\anaconda3\\envs\\study\\lib\\site-packages\\telegram\\ext\\updater.py\", line 651, in _network_loop_retry\n",
      "    if not action_cb():\n",
      "  File \"c:\\Users\\virtue\\anaconda3\\envs\\study\\lib\\site-packages\\telegram\\ext\\updater.py\", line 602, in polling_action_cb\n",
      "    updates = self.bot.get_updates(\n",
      "  File \"c:\\Users\\virtue\\anaconda3\\envs\\study\\lib\\site-packages\\telegram\\ext\\extbot.py\", line 226, in get_updates\n",
      "    updates = super().get_updates(\n",
      "  File \"c:\\Users\\virtue\\anaconda3\\envs\\study\\lib\\site-packages\\telegram\\bot.py\", line 133, in decorator\n",
      "    result = func(*args, **kwargs)\n",
      "  File \"c:\\Users\\virtue\\anaconda3\\envs\\study\\lib\\site-packages\\telegram\\bot.py\", line 3057, in get_updates\n",
      "    self._post(\n",
      "  File \"c:\\Users\\virtue\\anaconda3\\envs\\study\\lib\\site-packages\\telegram\\bot.py\", line 298, in _post\n",
      "    return self.request.post(\n",
      "  File \"c:\\Users\\virtue\\anaconda3\\envs\\study\\lib\\site-packages\\telegram\\utils\\request.py\", line 361, in post\n",
      "    result = self._request_wrapper(\n",
      "  File \"c:\\Users\\virtue\\anaconda3\\envs\\study\\lib\\site-packages\\telegram\\utils\\request.py\", line 283, in _request_wrapper\n",
      "    raise Conflict(message)\n",
      "telegram.error.Conflict: Conflict: terminated by other getUpdates request; make sure that only one bot instance is running\n",
      "Error while getting Updates: Conflict: terminated by other getUpdates request; make sure that only one bot instance is running\n",
      "No error handlers are registered, logging exception.\n",
      "Traceback (most recent call last):\n",
      "  File \"c:\\Users\\virtue\\anaconda3\\envs\\study\\lib\\site-packages\\telegram\\ext\\updater.py\", line 651, in _network_loop_retry\n",
      "    if not action_cb():\n",
      "  File \"c:\\Users\\virtue\\anaconda3\\envs\\study\\lib\\site-packages\\telegram\\ext\\updater.py\", line 602, in polling_action_cb\n",
      "    updates = self.bot.get_updates(\n",
      "  File \"c:\\Users\\virtue\\anaconda3\\envs\\study\\lib\\site-packages\\telegram\\ext\\extbot.py\", line 226, in get_updates\n",
      "    updates = super().get_updates(\n",
      "  File \"c:\\Users\\virtue\\anaconda3\\envs\\study\\lib\\site-packages\\telegram\\bot.py\", line 133, in decorator\n",
      "    result = func(*args, **kwargs)\n",
      "  File \"c:\\Users\\virtue\\anaconda3\\envs\\study\\lib\\site-packages\\telegram\\bot.py\", line 3057, in get_updates\n",
      "    self._post(\n",
      "  File \"c:\\Users\\virtue\\anaconda3\\envs\\study\\lib\\site-packages\\telegram\\bot.py\", line 298, in _post\n",
      "    return self.request.post(\n",
      "  File \"c:\\Users\\virtue\\anaconda3\\envs\\study\\lib\\site-packages\\telegram\\utils\\request.py\", line 361, in post\n",
      "    result = self._request_wrapper(\n",
      "  File \"c:\\Users\\virtue\\anaconda3\\envs\\study\\lib\\site-packages\\telegram\\utils\\request.py\", line 283, in _request_wrapper\n",
      "    raise Conflict(message)\n",
      "telegram.error.Conflict: Conflict: terminated by other getUpdates request; make sure that only one bot instance is running\n",
      "Error while getting Updates: Conflict: terminated by other getUpdates request; make sure that only one bot instance is running\n",
      "No error handlers are registered, logging exception.\n",
      "Traceback (most recent call last):\n",
      "  File \"c:\\Users\\virtue\\anaconda3\\envs\\study\\lib\\site-packages\\telegram\\ext\\updater.py\", line 651, in _network_loop_retry\n",
      "    if not action_cb():\n",
      "  File \"c:\\Users\\virtue\\anaconda3\\envs\\study\\lib\\site-packages\\telegram\\ext\\updater.py\", line 602, in polling_action_cb\n",
      "    updates = self.bot.get_updates(\n",
      "  File \"c:\\Users\\virtue\\anaconda3\\envs\\study\\lib\\site-packages\\telegram\\ext\\extbot.py\", line 226, in get_updates\n",
      "    updates = super().get_updates(\n",
      "  File \"c:\\Users\\virtue\\anaconda3\\envs\\study\\lib\\site-packages\\telegram\\bot.py\", line 133, in decorator\n",
      "    result = func(*args, **kwargs)\n",
      "  File \"c:\\Users\\virtue\\anaconda3\\envs\\study\\lib\\site-packages\\telegram\\bot.py\", line 3057, in get_updates\n",
      "    self._post(\n",
      "  File \"c:\\Users\\virtue\\anaconda3\\envs\\study\\lib\\site-packages\\telegram\\bot.py\", line 298, in _post\n",
      "    return self.request.post(\n",
      "  File \"c:\\Users\\virtue\\anaconda3\\envs\\study\\lib\\site-packages\\telegram\\utils\\request.py\", line 361, in post\n",
      "    result = self._request_wrapper(\n",
      "  File \"c:\\Users\\virtue\\anaconda3\\envs\\study\\lib\\site-packages\\telegram\\utils\\request.py\", line 283, in _request_wrapper\n",
      "    raise Conflict(message)\n",
      "telegram.error.Conflict: Conflict: terminated by other getUpdates request; make sure that only one bot instance is running\n",
      "Error while getting Updates: Conflict: terminated by other getUpdates request; make sure that only one bot instance is running\n",
      "No error handlers are registered, logging exception.\n",
      "Traceback (most recent call last):\n",
      "  File \"c:\\Users\\virtue\\anaconda3\\envs\\study\\lib\\site-packages\\telegram\\ext\\updater.py\", line 651, in _network_loop_retry\n",
      "    if not action_cb():\n",
      "  File \"c:\\Users\\virtue\\anaconda3\\envs\\study\\lib\\site-packages\\telegram\\ext\\updater.py\", line 602, in polling_action_cb\n",
      "    updates = self.bot.get_updates(\n",
      "  File \"c:\\Users\\virtue\\anaconda3\\envs\\study\\lib\\site-packages\\telegram\\ext\\extbot.py\", line 226, in get_updates\n",
      "    updates = super().get_updates(\n",
      "  File \"c:\\Users\\virtue\\anaconda3\\envs\\study\\lib\\site-packages\\telegram\\bot.py\", line 133, in decorator\n",
      "    result = func(*args, **kwargs)\n",
      "  File \"c:\\Users\\virtue\\anaconda3\\envs\\study\\lib\\site-packages\\telegram\\bot.py\", line 3057, in get_updates\n",
      "    self._post(\n",
      "  File \"c:\\Users\\virtue\\anaconda3\\envs\\study\\lib\\site-packages\\telegram\\bot.py\", line 298, in _post\n",
      "    return self.request.post(\n",
      "  File \"c:\\Users\\virtue\\anaconda3\\envs\\study\\lib\\site-packages\\telegram\\utils\\request.py\", line 361, in post\n",
      "    result = self._request_wrapper(\n",
      "  File \"c:\\Users\\virtue\\anaconda3\\envs\\study\\lib\\site-packages\\telegram\\utils\\request.py\", line 283, in _request_wrapper\n",
      "    raise Conflict(message)\n",
      "telegram.error.Conflict: Conflict: terminated by other getUpdates request; make sure that only one bot instance is running\n",
      "Error while getting Updates: Conflict: terminated by other getUpdates request; make sure that only one bot instance is running\n",
      "No error handlers are registered, logging exception.\n",
      "Traceback (most recent call last):\n",
      "  File \"c:\\Users\\virtue\\anaconda3\\envs\\study\\lib\\site-packages\\telegram\\ext\\updater.py\", line 651, in _network_loop_retry\n",
      "    if not action_cb():\n",
      "  File \"c:\\Users\\virtue\\anaconda3\\envs\\study\\lib\\site-packages\\telegram\\ext\\updater.py\", line 602, in polling_action_cb\n",
      "    updates = self.bot.get_updates(\n",
      "  File \"c:\\Users\\virtue\\anaconda3\\envs\\study\\lib\\site-packages\\telegram\\ext\\extbot.py\", line 226, in get_updates\n",
      "    updates = super().get_updates(\n",
      "  File \"c:\\Users\\virtue\\anaconda3\\envs\\study\\lib\\site-packages\\telegram\\bot.py\", line 133, in decorator\n",
      "    result = func(*args, **kwargs)\n",
      "  File \"c:\\Users\\virtue\\anaconda3\\envs\\study\\lib\\site-packages\\telegram\\bot.py\", line 3057, in get_updates\n",
      "    self._post(\n",
      "  File \"c:\\Users\\virtue\\anaconda3\\envs\\study\\lib\\site-packages\\telegram\\bot.py\", line 298, in _post\n",
      "    return self.request.post(\n",
      "  File \"c:\\Users\\virtue\\anaconda3\\envs\\study\\lib\\site-packages\\telegram\\utils\\request.py\", line 361, in post\n",
      "    result = self._request_wrapper(\n",
      "  File \"c:\\Users\\virtue\\anaconda3\\envs\\study\\lib\\site-packages\\telegram\\utils\\request.py\", line 283, in _request_wrapper\n",
      "    raise Conflict(message)\n",
      "telegram.error.Conflict: Conflict: terminated by other getUpdates request; make sure that only one bot instance is running\n",
      "Error while getting Updates: Conflict: terminated by other getUpdates request; make sure that only one bot instance is running\n",
      "No error handlers are registered, logging exception.\n",
      "Traceback (most recent call last):\n",
      "  File \"c:\\Users\\virtue\\anaconda3\\envs\\study\\lib\\site-packages\\telegram\\ext\\updater.py\", line 651, in _network_loop_retry\n",
      "    if not action_cb():\n",
      "  File \"c:\\Users\\virtue\\anaconda3\\envs\\study\\lib\\site-packages\\telegram\\ext\\updater.py\", line 602, in polling_action_cb\n",
      "    updates = self.bot.get_updates(\n",
      "  File \"c:\\Users\\virtue\\anaconda3\\envs\\study\\lib\\site-packages\\telegram\\ext\\extbot.py\", line 226, in get_updates\n",
      "    updates = super().get_updates(\n",
      "  File \"c:\\Users\\virtue\\anaconda3\\envs\\study\\lib\\site-packages\\telegram\\bot.py\", line 133, in decorator\n",
      "    result = func(*args, **kwargs)\n",
      "  File \"c:\\Users\\virtue\\anaconda3\\envs\\study\\lib\\site-packages\\telegram\\bot.py\", line 3057, in get_updates\n",
      "    self._post(\n",
      "  File \"c:\\Users\\virtue\\anaconda3\\envs\\study\\lib\\site-packages\\telegram\\bot.py\", line 298, in _post\n",
      "    return self.request.post(\n",
      "  File \"c:\\Users\\virtue\\anaconda3\\envs\\study\\lib\\site-packages\\telegram\\utils\\request.py\", line 361, in post\n",
      "    result = self._request_wrapper(\n",
      "  File \"c:\\Users\\virtue\\anaconda3\\envs\\study\\lib\\site-packages\\telegram\\utils\\request.py\", line 283, in _request_wrapper\n",
      "    raise Conflict(message)\n",
      "telegram.error.Conflict: Conflict: terminated by other getUpdates request; make sure that only one bot instance is running\n",
      "Error while getting Updates: Conflict: terminated by other getUpdates request; make sure that only one bot instance is running\n",
      "No error handlers are registered, logging exception.\n",
      "Traceback (most recent call last):\n",
      "  File \"c:\\Users\\virtue\\anaconda3\\envs\\study\\lib\\site-packages\\telegram\\ext\\updater.py\", line 651, in _network_loop_retry\n",
      "    if not action_cb():\n",
      "  File \"c:\\Users\\virtue\\anaconda3\\envs\\study\\lib\\site-packages\\telegram\\ext\\updater.py\", line 602, in polling_action_cb\n",
      "    updates = self.bot.get_updates(\n",
      "  File \"c:\\Users\\virtue\\anaconda3\\envs\\study\\lib\\site-packages\\telegram\\ext\\extbot.py\", line 226, in get_updates\n",
      "    updates = super().get_updates(\n",
      "  File \"c:\\Users\\virtue\\anaconda3\\envs\\study\\lib\\site-packages\\telegram\\bot.py\", line 133, in decorator\n",
      "    result = func(*args, **kwargs)\n",
      "  File \"c:\\Users\\virtue\\anaconda3\\envs\\study\\lib\\site-packages\\telegram\\bot.py\", line 3057, in get_updates\n",
      "    self._post(\n",
      "  File \"c:\\Users\\virtue\\anaconda3\\envs\\study\\lib\\site-packages\\telegram\\bot.py\", line 298, in _post\n",
      "    return self.request.post(\n",
      "  File \"c:\\Users\\virtue\\anaconda3\\envs\\study\\lib\\site-packages\\telegram\\utils\\request.py\", line 361, in post\n",
      "    result = self._request_wrapper(\n",
      "  File \"c:\\Users\\virtue\\anaconda3\\envs\\study\\lib\\site-packages\\telegram\\utils\\request.py\", line 283, in _request_wrapper\n",
      "    raise Conflict(message)\n",
      "telegram.error.Conflict: Conflict: terminated by other getUpdates request; make sure that only one bot instance is running\n",
      "Error while getting Updates: Conflict: terminated by other getUpdates request; make sure that only one bot instance is running\n",
      "No error handlers are registered, logging exception.\n",
      "Traceback (most recent call last):\n",
      "  File \"c:\\Users\\virtue\\anaconda3\\envs\\study\\lib\\site-packages\\telegram\\ext\\updater.py\", line 651, in _network_loop_retry\n",
      "    if not action_cb():\n",
      "  File \"c:\\Users\\virtue\\anaconda3\\envs\\study\\lib\\site-packages\\telegram\\ext\\updater.py\", line 602, in polling_action_cb\n",
      "    updates = self.bot.get_updates(\n",
      "  File \"c:\\Users\\virtue\\anaconda3\\envs\\study\\lib\\site-packages\\telegram\\ext\\extbot.py\", line 226, in get_updates\n",
      "    updates = super().get_updates(\n",
      "  File \"c:\\Users\\virtue\\anaconda3\\envs\\study\\lib\\site-packages\\telegram\\bot.py\", line 133, in decorator\n",
      "    result = func(*args, **kwargs)\n",
      "  File \"c:\\Users\\virtue\\anaconda3\\envs\\study\\lib\\site-packages\\telegram\\bot.py\", line 3057, in get_updates\n",
      "    self._post(\n",
      "  File \"c:\\Users\\virtue\\anaconda3\\envs\\study\\lib\\site-packages\\telegram\\bot.py\", line 298, in _post\n",
      "    return self.request.post(\n",
      "  File \"c:\\Users\\virtue\\anaconda3\\envs\\study\\lib\\site-packages\\telegram\\utils\\request.py\", line 361, in post\n",
      "    result = self._request_wrapper(\n",
      "  File \"c:\\Users\\virtue\\anaconda3\\envs\\study\\lib\\site-packages\\telegram\\utils\\request.py\", line 283, in _request_wrapper\n",
      "    raise Conflict(message)\n",
      "telegram.error.Conflict: Conflict: terminated by other getUpdates request; make sure that only one bot instance is running\n",
      "Error while getting Updates: Conflict: terminated by other getUpdates request; make sure that only one bot instance is running\n",
      "No error handlers are registered, logging exception.\n",
      "Traceback (most recent call last):\n",
      "  File \"c:\\Users\\virtue\\anaconda3\\envs\\study\\lib\\site-packages\\telegram\\ext\\updater.py\", line 651, in _network_loop_retry\n",
      "    if not action_cb():\n",
      "  File \"c:\\Users\\virtue\\anaconda3\\envs\\study\\lib\\site-packages\\telegram\\ext\\updater.py\", line 602, in polling_action_cb\n",
      "    updates = self.bot.get_updates(\n",
      "  File \"c:\\Users\\virtue\\anaconda3\\envs\\study\\lib\\site-packages\\telegram\\ext\\extbot.py\", line 226, in get_updates\n",
      "    updates = super().get_updates(\n",
      "  File \"c:\\Users\\virtue\\anaconda3\\envs\\study\\lib\\site-packages\\telegram\\bot.py\", line 133, in decorator\n",
      "    result = func(*args, **kwargs)\n",
      "  File \"c:\\Users\\virtue\\anaconda3\\envs\\study\\lib\\site-packages\\telegram\\bot.py\", line 3057, in get_updates\n",
      "    self._post(\n",
      "  File \"c:\\Users\\virtue\\anaconda3\\envs\\study\\lib\\site-packages\\telegram\\bot.py\", line 298, in _post\n",
      "    return self.request.post(\n",
      "  File \"c:\\Users\\virtue\\anaconda3\\envs\\study\\lib\\site-packages\\telegram\\utils\\request.py\", line 361, in post\n",
      "    result = self._request_wrapper(\n",
      "  File \"c:\\Users\\virtue\\anaconda3\\envs\\study\\lib\\site-packages\\telegram\\utils\\request.py\", line 283, in _request_wrapper\n",
      "    raise Conflict(message)\n",
      "telegram.error.Conflict: Conflict: terminated by other getUpdates request; make sure that only one bot instance is running\n",
      "Error while getting Updates: Conflict: terminated by other getUpdates request; make sure that only one bot instance is running\n",
      "No error handlers are registered, logging exception.\n",
      "Traceback (most recent call last):\n",
      "  File \"c:\\Users\\virtue\\anaconda3\\envs\\study\\lib\\site-packages\\telegram\\ext\\updater.py\", line 651, in _network_loop_retry\n",
      "    if not action_cb():\n",
      "  File \"c:\\Users\\virtue\\anaconda3\\envs\\study\\lib\\site-packages\\telegram\\ext\\updater.py\", line 602, in polling_action_cb\n",
      "    updates = self.bot.get_updates(\n",
      "  File \"c:\\Users\\virtue\\anaconda3\\envs\\study\\lib\\site-packages\\telegram\\ext\\extbot.py\", line 226, in get_updates\n",
      "    updates = super().get_updates(\n",
      "  File \"c:\\Users\\virtue\\anaconda3\\envs\\study\\lib\\site-packages\\telegram\\bot.py\", line 133, in decorator\n",
      "    result = func(*args, **kwargs)\n",
      "  File \"c:\\Users\\virtue\\anaconda3\\envs\\study\\lib\\site-packages\\telegram\\bot.py\", line 3057, in get_updates\n",
      "    self._post(\n",
      "  File \"c:\\Users\\virtue\\anaconda3\\envs\\study\\lib\\site-packages\\telegram\\bot.py\", line 298, in _post\n",
      "    return self.request.post(\n",
      "  File \"c:\\Users\\virtue\\anaconda3\\envs\\study\\lib\\site-packages\\telegram\\utils\\request.py\", line 361, in post\n",
      "    result = self._request_wrapper(\n",
      "  File \"c:\\Users\\virtue\\anaconda3\\envs\\study\\lib\\site-packages\\telegram\\utils\\request.py\", line 283, in _request_wrapper\n",
      "    raise Conflict(message)\n",
      "telegram.error.Conflict: Conflict: terminated by other getUpdates request; make sure that only one bot instance is running\n",
      "Error while getting Updates: Conflict: terminated by other getUpdates request; make sure that only one bot instance is running\n",
      "No error handlers are registered, logging exception.\n",
      "Traceback (most recent call last):\n",
      "  File \"c:\\Users\\virtue\\anaconda3\\envs\\study\\lib\\site-packages\\telegram\\ext\\updater.py\", line 651, in _network_loop_retry\n",
      "    if not action_cb():\n",
      "  File \"c:\\Users\\virtue\\anaconda3\\envs\\study\\lib\\site-packages\\telegram\\ext\\updater.py\", line 602, in polling_action_cb\n",
      "    updates = self.bot.get_updates(\n",
      "  File \"c:\\Users\\virtue\\anaconda3\\envs\\study\\lib\\site-packages\\telegram\\ext\\extbot.py\", line 226, in get_updates\n",
      "    updates = super().get_updates(\n",
      "  File \"c:\\Users\\virtue\\anaconda3\\envs\\study\\lib\\site-packages\\telegram\\bot.py\", line 133, in decorator\n",
      "    result = func(*args, **kwargs)\n",
      "  File \"c:\\Users\\virtue\\anaconda3\\envs\\study\\lib\\site-packages\\telegram\\bot.py\", line 3057, in get_updates\n",
      "    self._post(\n",
      "  File \"c:\\Users\\virtue\\anaconda3\\envs\\study\\lib\\site-packages\\telegram\\bot.py\", line 298, in _post\n",
      "    return self.request.post(\n",
      "  File \"c:\\Users\\virtue\\anaconda3\\envs\\study\\lib\\site-packages\\telegram\\utils\\request.py\", line 361, in post\n",
      "    result = self._request_wrapper(\n",
      "  File \"c:\\Users\\virtue\\anaconda3\\envs\\study\\lib\\site-packages\\telegram\\utils\\request.py\", line 283, in _request_wrapper\n",
      "    raise Conflict(message)\n",
      "telegram.error.Conflict: Conflict: terminated by other getUpdates request; make sure that only one bot instance is running\n",
      "Error while getting Updates: Conflict: terminated by other getUpdates request; make sure that only one bot instance is running\n",
      "No error handlers are registered, logging exception.\n",
      "Traceback (most recent call last):\n",
      "  File \"c:\\Users\\virtue\\anaconda3\\envs\\study\\lib\\site-packages\\telegram\\ext\\updater.py\", line 651, in _network_loop_retry\n",
      "    if not action_cb():\n",
      "  File \"c:\\Users\\virtue\\anaconda3\\envs\\study\\lib\\site-packages\\telegram\\ext\\updater.py\", line 602, in polling_action_cb\n",
      "    updates = self.bot.get_updates(\n",
      "  File \"c:\\Users\\virtue\\anaconda3\\envs\\study\\lib\\site-packages\\telegram\\ext\\extbot.py\", line 226, in get_updates\n",
      "    updates = super().get_updates(\n",
      "  File \"c:\\Users\\virtue\\anaconda3\\envs\\study\\lib\\site-packages\\telegram\\bot.py\", line 133, in decorator\n",
      "    result = func(*args, **kwargs)\n",
      "  File \"c:\\Users\\virtue\\anaconda3\\envs\\study\\lib\\site-packages\\telegram\\bot.py\", line 3057, in get_updates\n",
      "    self._post(\n",
      "  File \"c:\\Users\\virtue\\anaconda3\\envs\\study\\lib\\site-packages\\telegram\\bot.py\", line 298, in _post\n",
      "    return self.request.post(\n",
      "  File \"c:\\Users\\virtue\\anaconda3\\envs\\study\\lib\\site-packages\\telegram\\utils\\request.py\", line 361, in post\n",
      "    result = self._request_wrapper(\n",
      "  File \"c:\\Users\\virtue\\anaconda3\\envs\\study\\lib\\site-packages\\telegram\\utils\\request.py\", line 283, in _request_wrapper\n",
      "    raise Conflict(message)\n",
      "telegram.error.Conflict: Conflict: terminated by other getUpdates request; make sure that only one bot instance is running\n",
      "Error while getting Updates: Conflict: terminated by other getUpdates request; make sure that only one bot instance is running\n",
      "No error handlers are registered, logging exception.\n",
      "Traceback (most recent call last):\n",
      "  File \"c:\\Users\\virtue\\anaconda3\\envs\\study\\lib\\site-packages\\telegram\\ext\\updater.py\", line 651, in _network_loop_retry\n",
      "    if not action_cb():\n",
      "  File \"c:\\Users\\virtue\\anaconda3\\envs\\study\\lib\\site-packages\\telegram\\ext\\updater.py\", line 602, in polling_action_cb\n",
      "    updates = self.bot.get_updates(\n",
      "  File \"c:\\Users\\virtue\\anaconda3\\envs\\study\\lib\\site-packages\\telegram\\ext\\extbot.py\", line 226, in get_updates\n",
      "    updates = super().get_updates(\n",
      "  File \"c:\\Users\\virtue\\anaconda3\\envs\\study\\lib\\site-packages\\telegram\\bot.py\", line 133, in decorator\n",
      "    result = func(*args, **kwargs)\n",
      "  File \"c:\\Users\\virtue\\anaconda3\\envs\\study\\lib\\site-packages\\telegram\\bot.py\", line 3057, in get_updates\n",
      "    self._post(\n",
      "  File \"c:\\Users\\virtue\\anaconda3\\envs\\study\\lib\\site-packages\\telegram\\bot.py\", line 298, in _post\n",
      "    return self.request.post(\n",
      "  File \"c:\\Users\\virtue\\anaconda3\\envs\\study\\lib\\site-packages\\telegram\\utils\\request.py\", line 361, in post\n",
      "    result = self._request_wrapper(\n",
      "  File \"c:\\Users\\virtue\\anaconda3\\envs\\study\\lib\\site-packages\\telegram\\utils\\request.py\", line 283, in _request_wrapper\n",
      "    raise Conflict(message)\n",
      "telegram.error.Conflict: Conflict: terminated by other getUpdates request; make sure that only one bot instance is running\n",
      "Error while getting Updates: Conflict: terminated by other getUpdates request; make sure that only one bot instance is running\n",
      "No error handlers are registered, logging exception.\n",
      "Traceback (most recent call last):\n",
      "  File \"c:\\Users\\virtue\\anaconda3\\envs\\study\\lib\\site-packages\\telegram\\ext\\updater.py\", line 651, in _network_loop_retry\n",
      "    if not action_cb():\n",
      "  File \"c:\\Users\\virtue\\anaconda3\\envs\\study\\lib\\site-packages\\telegram\\ext\\updater.py\", line 602, in polling_action_cb\n",
      "    updates = self.bot.get_updates(\n",
      "  File \"c:\\Users\\virtue\\anaconda3\\envs\\study\\lib\\site-packages\\telegram\\ext\\extbot.py\", line 226, in get_updates\n",
      "    updates = super().get_updates(\n",
      "  File \"c:\\Users\\virtue\\anaconda3\\envs\\study\\lib\\site-packages\\telegram\\bot.py\", line 133, in decorator\n",
      "    result = func(*args, **kwargs)\n",
      "  File \"c:\\Users\\virtue\\anaconda3\\envs\\study\\lib\\site-packages\\telegram\\bot.py\", line 3057, in get_updates\n",
      "    self._post(\n",
      "  File \"c:\\Users\\virtue\\anaconda3\\envs\\study\\lib\\site-packages\\telegram\\bot.py\", line 298, in _post\n",
      "    return self.request.post(\n",
      "  File \"c:\\Users\\virtue\\anaconda3\\envs\\study\\lib\\site-packages\\telegram\\utils\\request.py\", line 361, in post\n",
      "    result = self._request_wrapper(\n",
      "  File \"c:\\Users\\virtue\\anaconda3\\envs\\study\\lib\\site-packages\\telegram\\utils\\request.py\", line 283, in _request_wrapper\n",
      "    raise Conflict(message)\n",
      "telegram.error.Conflict: Conflict: terminated by other getUpdates request; make sure that only one bot instance is running\n",
      "Error while getting Updates: Conflict: terminated by other getUpdates request; make sure that only one bot instance is running\n",
      "No error handlers are registered, logging exception.\n",
      "Traceback (most recent call last):\n",
      "  File \"c:\\Users\\virtue\\anaconda3\\envs\\study\\lib\\site-packages\\telegram\\ext\\updater.py\", line 651, in _network_loop_retry\n",
      "    if not action_cb():\n",
      "  File \"c:\\Users\\virtue\\anaconda3\\envs\\study\\lib\\site-packages\\telegram\\ext\\updater.py\", line 602, in polling_action_cb\n",
      "    updates = self.bot.get_updates(\n",
      "  File \"c:\\Users\\virtue\\anaconda3\\envs\\study\\lib\\site-packages\\telegram\\ext\\extbot.py\", line 226, in get_updates\n",
      "    updates = super().get_updates(\n",
      "  File \"c:\\Users\\virtue\\anaconda3\\envs\\study\\lib\\site-packages\\telegram\\bot.py\", line 133, in decorator\n",
      "    result = func(*args, **kwargs)\n",
      "  File \"c:\\Users\\virtue\\anaconda3\\envs\\study\\lib\\site-packages\\telegram\\bot.py\", line 3057, in get_updates\n",
      "    self._post(\n",
      "  File \"c:\\Users\\virtue\\anaconda3\\envs\\study\\lib\\site-packages\\telegram\\bot.py\", line 298, in _post\n",
      "    return self.request.post(\n",
      "  File \"c:\\Users\\virtue\\anaconda3\\envs\\study\\lib\\site-packages\\telegram\\utils\\request.py\", line 361, in post\n",
      "    result = self._request_wrapper(\n",
      "  File \"c:\\Users\\virtue\\anaconda3\\envs\\study\\lib\\site-packages\\telegram\\utils\\request.py\", line 283, in _request_wrapper\n",
      "    raise Conflict(message)\n",
      "telegram.error.Conflict: Conflict: terminated by other getUpdates request; make sure that only one bot instance is running\n",
      "Error while getting Updates: Conflict: terminated by other getUpdates request; make sure that only one bot instance is running\n",
      "No error handlers are registered, logging exception.\n",
      "Traceback (most recent call last):\n",
      "  File \"c:\\Users\\virtue\\anaconda3\\envs\\study\\lib\\site-packages\\telegram\\ext\\updater.py\", line 651, in _network_loop_retry\n",
      "    if not action_cb():\n",
      "  File \"c:\\Users\\virtue\\anaconda3\\envs\\study\\lib\\site-packages\\telegram\\ext\\updater.py\", line 602, in polling_action_cb\n",
      "    updates = self.bot.get_updates(\n",
      "  File \"c:\\Users\\virtue\\anaconda3\\envs\\study\\lib\\site-packages\\telegram\\ext\\extbot.py\", line 226, in get_updates\n",
      "    updates = super().get_updates(\n",
      "  File \"c:\\Users\\virtue\\anaconda3\\envs\\study\\lib\\site-packages\\telegram\\bot.py\", line 133, in decorator\n",
      "    result = func(*args, **kwargs)\n",
      "  File \"c:\\Users\\virtue\\anaconda3\\envs\\study\\lib\\site-packages\\telegram\\bot.py\", line 3057, in get_updates\n",
      "    self._post(\n",
      "  File \"c:\\Users\\virtue\\anaconda3\\envs\\study\\lib\\site-packages\\telegram\\bot.py\", line 298, in _post\n",
      "    return self.request.post(\n",
      "  File \"c:\\Users\\virtue\\anaconda3\\envs\\study\\lib\\site-packages\\telegram\\utils\\request.py\", line 361, in post\n",
      "    result = self._request_wrapper(\n",
      "  File \"c:\\Users\\virtue\\anaconda3\\envs\\study\\lib\\site-packages\\telegram\\utils\\request.py\", line 283, in _request_wrapper\n",
      "    raise Conflict(message)\n",
      "telegram.error.Conflict: Conflict: terminated by other getUpdates request; make sure that only one bot instance is running\n",
      "Error while getting Updates: Conflict: terminated by other getUpdates request; make sure that only one bot instance is running\n",
      "No error handlers are registered, logging exception.\n",
      "Traceback (most recent call last):\n",
      "  File \"c:\\Users\\virtue\\anaconda3\\envs\\study\\lib\\site-packages\\telegram\\ext\\updater.py\", line 651, in _network_loop_retry\n",
      "    if not action_cb():\n",
      "  File \"c:\\Users\\virtue\\anaconda3\\envs\\study\\lib\\site-packages\\telegram\\ext\\updater.py\", line 602, in polling_action_cb\n",
      "    updates = self.bot.get_updates(\n",
      "  File \"c:\\Users\\virtue\\anaconda3\\envs\\study\\lib\\site-packages\\telegram\\ext\\extbot.py\", line 226, in get_updates\n",
      "    updates = super().get_updates(\n",
      "  File \"c:\\Users\\virtue\\anaconda3\\envs\\study\\lib\\site-packages\\telegram\\bot.py\", line 133, in decorator\n",
      "    result = func(*args, **kwargs)\n",
      "  File \"c:\\Users\\virtue\\anaconda3\\envs\\study\\lib\\site-packages\\telegram\\bot.py\", line 3057, in get_updates\n",
      "    self._post(\n",
      "  File \"c:\\Users\\virtue\\anaconda3\\envs\\study\\lib\\site-packages\\telegram\\bot.py\", line 298, in _post\n",
      "    return self.request.post(\n",
      "  File \"c:\\Users\\virtue\\anaconda3\\envs\\study\\lib\\site-packages\\telegram\\utils\\request.py\", line 361, in post\n",
      "    result = self._request_wrapper(\n",
      "  File \"c:\\Users\\virtue\\anaconda3\\envs\\study\\lib\\site-packages\\telegram\\utils\\request.py\", line 283, in _request_wrapper\n",
      "    raise Conflict(message)\n",
      "telegram.error.Conflict: Conflict: terminated by other getUpdates request; make sure that only one bot instance is running\n",
      "Error while getting Updates: Conflict: terminated by other getUpdates request; make sure that only one bot instance is running\n",
      "No error handlers are registered, logging exception.\n",
      "Traceback (most recent call last):\n",
      "  File \"c:\\Users\\virtue\\anaconda3\\envs\\study\\lib\\site-packages\\telegram\\ext\\updater.py\", line 651, in _network_loop_retry\n",
      "    if not action_cb():\n",
      "  File \"c:\\Users\\virtue\\anaconda3\\envs\\study\\lib\\site-packages\\telegram\\ext\\updater.py\", line 602, in polling_action_cb\n",
      "    updates = self.bot.get_updates(\n",
      "  File \"c:\\Users\\virtue\\anaconda3\\envs\\study\\lib\\site-packages\\telegram\\ext\\extbot.py\", line 226, in get_updates\n",
      "    updates = super().get_updates(\n",
      "  File \"c:\\Users\\virtue\\anaconda3\\envs\\study\\lib\\site-packages\\telegram\\bot.py\", line 133, in decorator\n",
      "    result = func(*args, **kwargs)\n",
      "  File \"c:\\Users\\virtue\\anaconda3\\envs\\study\\lib\\site-packages\\telegram\\bot.py\", line 3057, in get_updates\n",
      "    self._post(\n",
      "  File \"c:\\Users\\virtue\\anaconda3\\envs\\study\\lib\\site-packages\\telegram\\bot.py\", line 298, in _post\n",
      "    return self.request.post(\n",
      "  File \"c:\\Users\\virtue\\anaconda3\\envs\\study\\lib\\site-packages\\telegram\\utils\\request.py\", line 361, in post\n",
      "    result = self._request_wrapper(\n",
      "  File \"c:\\Users\\virtue\\anaconda3\\envs\\study\\lib\\site-packages\\telegram\\utils\\request.py\", line 283, in _request_wrapper\n",
      "    raise Conflict(message)\n",
      "telegram.error.Conflict: Conflict: terminated by other getUpdates request; make sure that only one bot instance is running\n",
      "Error while getting Updates: Conflict: terminated by other getUpdates request; make sure that only one bot instance is running\n",
      "No error handlers are registered, logging exception.\n",
      "Traceback (most recent call last):\n",
      "  File \"c:\\Users\\virtue\\anaconda3\\envs\\study\\lib\\site-packages\\telegram\\ext\\updater.py\", line 651, in _network_loop_retry\n",
      "    if not action_cb():\n",
      "  File \"c:\\Users\\virtue\\anaconda3\\envs\\study\\lib\\site-packages\\telegram\\ext\\updater.py\", line 602, in polling_action_cb\n",
      "    updates = self.bot.get_updates(\n",
      "  File \"c:\\Users\\virtue\\anaconda3\\envs\\study\\lib\\site-packages\\telegram\\ext\\extbot.py\", line 226, in get_updates\n",
      "    updates = super().get_updates(\n",
      "  File \"c:\\Users\\virtue\\anaconda3\\envs\\study\\lib\\site-packages\\telegram\\bot.py\", line 133, in decorator\n",
      "    result = func(*args, **kwargs)\n",
      "  File \"c:\\Users\\virtue\\anaconda3\\envs\\study\\lib\\site-packages\\telegram\\bot.py\", line 3057, in get_updates\n",
      "    self._post(\n",
      "  File \"c:\\Users\\virtue\\anaconda3\\envs\\study\\lib\\site-packages\\telegram\\bot.py\", line 298, in _post\n",
      "    return self.request.post(\n",
      "  File \"c:\\Users\\virtue\\anaconda3\\envs\\study\\lib\\site-packages\\telegram\\utils\\request.py\", line 361, in post\n",
      "    result = self._request_wrapper(\n",
      "  File \"c:\\Users\\virtue\\anaconda3\\envs\\study\\lib\\site-packages\\telegram\\utils\\request.py\", line 283, in _request_wrapper\n",
      "    raise Conflict(message)\n",
      "telegram.error.Conflict: Conflict: terminated by other getUpdates request; make sure that only one bot instance is running\n",
      "Error while getting Updates: Conflict: terminated by other getUpdates request; make sure that only one bot instance is running\n",
      "No error handlers are registered, logging exception.\n",
      "Traceback (most recent call last):\n",
      "  File \"c:\\Users\\virtue\\anaconda3\\envs\\study\\lib\\site-packages\\telegram\\ext\\updater.py\", line 651, in _network_loop_retry\n",
      "    if not action_cb():\n",
      "  File \"c:\\Users\\virtue\\anaconda3\\envs\\study\\lib\\site-packages\\telegram\\ext\\updater.py\", line 602, in polling_action_cb\n",
      "    updates = self.bot.get_updates(\n",
      "  File \"c:\\Users\\virtue\\anaconda3\\envs\\study\\lib\\site-packages\\telegram\\ext\\extbot.py\", line 226, in get_updates\n",
      "    updates = super().get_updates(\n",
      "  File \"c:\\Users\\virtue\\anaconda3\\envs\\study\\lib\\site-packages\\telegram\\bot.py\", line 133, in decorator\n",
      "    result = func(*args, **kwargs)\n",
      "  File \"c:\\Users\\virtue\\anaconda3\\envs\\study\\lib\\site-packages\\telegram\\bot.py\", line 3057, in get_updates\n",
      "    self._post(\n",
      "  File \"c:\\Users\\virtue\\anaconda3\\envs\\study\\lib\\site-packages\\telegram\\bot.py\", line 298, in _post\n",
      "    return self.request.post(\n",
      "  File \"c:\\Users\\virtue\\anaconda3\\envs\\study\\lib\\site-packages\\telegram\\utils\\request.py\", line 361, in post\n",
      "    result = self._request_wrapper(\n",
      "  File \"c:\\Users\\virtue\\anaconda3\\envs\\study\\lib\\site-packages\\telegram\\utils\\request.py\", line 283, in _request_wrapper\n",
      "    raise Conflict(message)\n",
      "telegram.error.Conflict: Conflict: terminated by other getUpdates request; make sure that only one bot instance is running\n",
      "Error while getting Updates: Conflict: terminated by other getUpdates request; make sure that only one bot instance is running\n",
      "No error handlers are registered, logging exception.\n",
      "Traceback (most recent call last):\n",
      "  File \"c:\\Users\\virtue\\anaconda3\\envs\\study\\lib\\site-packages\\telegram\\ext\\updater.py\", line 651, in _network_loop_retry\n",
      "    if not action_cb():\n",
      "  File \"c:\\Users\\virtue\\anaconda3\\envs\\study\\lib\\site-packages\\telegram\\ext\\updater.py\", line 602, in polling_action_cb\n",
      "    updates = self.bot.get_updates(\n",
      "  File \"c:\\Users\\virtue\\anaconda3\\envs\\study\\lib\\site-packages\\telegram\\ext\\extbot.py\", line 226, in get_updates\n",
      "    updates = super().get_updates(\n",
      "  File \"c:\\Users\\virtue\\anaconda3\\envs\\study\\lib\\site-packages\\telegram\\bot.py\", line 133, in decorator\n",
      "    result = func(*args, **kwargs)\n",
      "  File \"c:\\Users\\virtue\\anaconda3\\envs\\study\\lib\\site-packages\\telegram\\bot.py\", line 3057, in get_updates\n",
      "    self._post(\n",
      "  File \"c:\\Users\\virtue\\anaconda3\\envs\\study\\lib\\site-packages\\telegram\\bot.py\", line 298, in _post\n",
      "    return self.request.post(\n",
      "  File \"c:\\Users\\virtue\\anaconda3\\envs\\study\\lib\\site-packages\\telegram\\utils\\request.py\", line 361, in post\n",
      "    result = self._request_wrapper(\n",
      "  File \"c:\\Users\\virtue\\anaconda3\\envs\\study\\lib\\site-packages\\telegram\\utils\\request.py\", line 283, in _request_wrapper\n",
      "    raise Conflict(message)\n",
      "telegram.error.Conflict: Conflict: terminated by other getUpdates request; make sure that only one bot instance is running\n",
      "Error while getting Updates: Conflict: terminated by other getUpdates request; make sure that only one bot instance is running\n",
      "No error handlers are registered, logging exception.\n",
      "Traceback (most recent call last):\n",
      "  File \"c:\\Users\\virtue\\anaconda3\\envs\\study\\lib\\site-packages\\telegram\\ext\\updater.py\", line 651, in _network_loop_retry\n",
      "    if not action_cb():\n",
      "  File \"c:\\Users\\virtue\\anaconda3\\envs\\study\\lib\\site-packages\\telegram\\ext\\updater.py\", line 602, in polling_action_cb\n",
      "    updates = self.bot.get_updates(\n",
      "  File \"c:\\Users\\virtue\\anaconda3\\envs\\study\\lib\\site-packages\\telegram\\ext\\extbot.py\", line 226, in get_updates\n",
      "    updates = super().get_updates(\n",
      "  File \"c:\\Users\\virtue\\anaconda3\\envs\\study\\lib\\site-packages\\telegram\\bot.py\", line 133, in decorator\n",
      "    result = func(*args, **kwargs)\n",
      "  File \"c:\\Users\\virtue\\anaconda3\\envs\\study\\lib\\site-packages\\telegram\\bot.py\", line 3057, in get_updates\n",
      "    self._post(\n",
      "  File \"c:\\Users\\virtue\\anaconda3\\envs\\study\\lib\\site-packages\\telegram\\bot.py\", line 298, in _post\n",
      "    return self.request.post(\n",
      "  File \"c:\\Users\\virtue\\anaconda3\\envs\\study\\lib\\site-packages\\telegram\\utils\\request.py\", line 361, in post\n",
      "    result = self._request_wrapper(\n",
      "  File \"c:\\Users\\virtue\\anaconda3\\envs\\study\\lib\\site-packages\\telegram\\utils\\request.py\", line 283, in _request_wrapper\n",
      "    raise Conflict(message)\n",
      "telegram.error.Conflict: Conflict: terminated by other getUpdates request; make sure that only one bot instance is running\n",
      "Error while getting Updates: Conflict: terminated by other getUpdates request; make sure that only one bot instance is running\n",
      "No error handlers are registered, logging exception.\n",
      "Traceback (most recent call last):\n",
      "  File \"c:\\Users\\virtue\\anaconda3\\envs\\study\\lib\\site-packages\\telegram\\ext\\updater.py\", line 651, in _network_loop_retry\n",
      "    if not action_cb():\n",
      "  File \"c:\\Users\\virtue\\anaconda3\\envs\\study\\lib\\site-packages\\telegram\\ext\\updater.py\", line 602, in polling_action_cb\n",
      "    updates = self.bot.get_updates(\n",
      "  File \"c:\\Users\\virtue\\anaconda3\\envs\\study\\lib\\site-packages\\telegram\\ext\\extbot.py\", line 226, in get_updates\n",
      "    updates = super().get_updates(\n",
      "  File \"c:\\Users\\virtue\\anaconda3\\envs\\study\\lib\\site-packages\\telegram\\bot.py\", line 133, in decorator\n",
      "    result = func(*args, **kwargs)\n",
      "  File \"c:\\Users\\virtue\\anaconda3\\envs\\study\\lib\\site-packages\\telegram\\bot.py\", line 3057, in get_updates\n",
      "    self._post(\n",
      "  File \"c:\\Users\\virtue\\anaconda3\\envs\\study\\lib\\site-packages\\telegram\\bot.py\", line 298, in _post\n",
      "    return self.request.post(\n",
      "  File \"c:\\Users\\virtue\\anaconda3\\envs\\study\\lib\\site-packages\\telegram\\utils\\request.py\", line 361, in post\n",
      "    result = self._request_wrapper(\n",
      "  File \"c:\\Users\\virtue\\anaconda3\\envs\\study\\lib\\site-packages\\telegram\\utils\\request.py\", line 283, in _request_wrapper\n",
      "    raise Conflict(message)\n",
      "telegram.error.Conflict: Conflict: terminated by other getUpdates request; make sure that only one bot instance is running\n",
      "Error while getting Updates: Conflict: terminated by other getUpdates request; make sure that only one bot instance is running\n",
      "No error handlers are registered, logging exception.\n",
      "Traceback (most recent call last):\n",
      "  File \"c:\\Users\\virtue\\anaconda3\\envs\\study\\lib\\site-packages\\telegram\\ext\\updater.py\", line 651, in _network_loop_retry\n",
      "    if not action_cb():\n",
      "  File \"c:\\Users\\virtue\\anaconda3\\envs\\study\\lib\\site-packages\\telegram\\ext\\updater.py\", line 602, in polling_action_cb\n",
      "    updates = self.bot.get_updates(\n",
      "  File \"c:\\Users\\virtue\\anaconda3\\envs\\study\\lib\\site-packages\\telegram\\ext\\extbot.py\", line 226, in get_updates\n",
      "    updates = super().get_updates(\n",
      "  File \"c:\\Users\\virtue\\anaconda3\\envs\\study\\lib\\site-packages\\telegram\\bot.py\", line 133, in decorator\n",
      "    result = func(*args, **kwargs)\n",
      "  File \"c:\\Users\\virtue\\anaconda3\\envs\\study\\lib\\site-packages\\telegram\\bot.py\", line 3057, in get_updates\n",
      "    self._post(\n",
      "  File \"c:\\Users\\virtue\\anaconda3\\envs\\study\\lib\\site-packages\\telegram\\bot.py\", line 298, in _post\n",
      "    return self.request.post(\n",
      "  File \"c:\\Users\\virtue\\anaconda3\\envs\\study\\lib\\site-packages\\telegram\\utils\\request.py\", line 361, in post\n",
      "    result = self._request_wrapper(\n",
      "  File \"c:\\Users\\virtue\\anaconda3\\envs\\study\\lib\\site-packages\\telegram\\utils\\request.py\", line 283, in _request_wrapper\n",
      "    raise Conflict(message)\n",
      "telegram.error.Conflict: Conflict: terminated by other getUpdates request; make sure that only one bot instance is running\n",
      "Error while getting Updates: Conflict: terminated by other getUpdates request; make sure that only one bot instance is running\n",
      "No error handlers are registered, logging exception.\n",
      "Traceback (most recent call last):\n",
      "  File \"c:\\Users\\virtue\\anaconda3\\envs\\study\\lib\\site-packages\\telegram\\ext\\updater.py\", line 651, in _network_loop_retry\n",
      "    if not action_cb():\n",
      "  File \"c:\\Users\\virtue\\anaconda3\\envs\\study\\lib\\site-packages\\telegram\\ext\\updater.py\", line 602, in polling_action_cb\n",
      "    updates = self.bot.get_updates(\n",
      "  File \"c:\\Users\\virtue\\anaconda3\\envs\\study\\lib\\site-packages\\telegram\\ext\\extbot.py\", line 226, in get_updates\n",
      "    updates = super().get_updates(\n",
      "  File \"c:\\Users\\virtue\\anaconda3\\envs\\study\\lib\\site-packages\\telegram\\bot.py\", line 133, in decorator\n",
      "    result = func(*args, **kwargs)\n",
      "  File \"c:\\Users\\virtue\\anaconda3\\envs\\study\\lib\\site-packages\\telegram\\bot.py\", line 3057, in get_updates\n",
      "    self._post(\n",
      "  File \"c:\\Users\\virtue\\anaconda3\\envs\\study\\lib\\site-packages\\telegram\\bot.py\", line 298, in _post\n",
      "    return self.request.post(\n",
      "  File \"c:\\Users\\virtue\\anaconda3\\envs\\study\\lib\\site-packages\\telegram\\utils\\request.py\", line 361, in post\n",
      "    result = self._request_wrapper(\n",
      "  File \"c:\\Users\\virtue\\anaconda3\\envs\\study\\lib\\site-packages\\telegram\\utils\\request.py\", line 283, in _request_wrapper\n",
      "    raise Conflict(message)\n",
      "telegram.error.Conflict: Conflict: terminated by other getUpdates request; make sure that only one bot instance is running\n"
     ]
    }
   ],
   "source": [
    "token = \"5429356985:AAGz0DTnMrMk2uD-UAlXOFVRN4bLEgwdDs0\"\n",
    "id = \"5637648634\"\n",
    "\n",
    "\n",
    "bot = telegram.Bot(token)\n",
    "info_message = '''<봇 키워드 설명>\n",
    "- 영상: EBS 세계테마기행 <스페인> 영상 \n",
    "- 정보: 네이버 두산백과 <스페인> 간략 정보 '''\n",
    "\n",
    "bot.sendMessage(chat_id=id, text=info_message)\n",
    " \n",
    "updater = Updater(token=token, use_context=True)\n",
    "dispatcher = updater.dispatcher\n",
    "updater.start_polling()\n",
    " \n",
    " ### 챗봇 답장\n",
    "def handler(update, context):\n",
    "    user_text = update.message.text # 사용자가 보낸 메세지를 user_text 변수에 저장\n",
    "    # 영상 리스트 전송\n",
    "    if (user_text == '영상'):\n",
    "        vod = ebs_crawling()\n",
    "        bot.send_message(chat_id=id, text=vod)\n",
    "        bot.sendMessage(chat_id=id, text=info_message)\n",
    "    # 관련 이미지 답장\n",
    "    elif (user_text == '정보'):\n",
    "        data = naver_crawling()\n",
    "        bot.send_message(chat_id=id, text=data)\n",
    "        bot.sendMessage(chat_id=id, text=info_message)\n",
    "    # \n",
    "    #       (user_text == \"이미지\"):\n",
    "    #     bot.send_message(chat_id=id, text=\"최신 이미지 크롤링 중...\")\n",
    "    #     covid_image_crawling(image_num=10)\n",
    "    #     # 이미지 한장만 보내기\n",
    "    #     # bot.send_photo(chat_id=id, photo=open(\"./코로나이미지/0.png\", 'rb'))\n",
    "    #     # 이미지 여러장 묶어서 보내기\n",
    "    #     photo_list = []\n",
    "    #     for i in range(len(os.walk(\"./코로나이미지\").__next__()[2])): # 이미지 파일 개수만큼 for문 돌리기\n",
    "    #         photo_list.append(telegram.InputMediaPhoto(open(\"./코로나이미지/{}.png\".format(i), \"rb\")))\n",
    "    #     bot.sendMediaGroup(chat_id=id, media=photo_list)\n",
    "    #     bot.sendMessage(chat_id=id, text=info_message)\n",
    "      \n",
    "    \n",
    "        \n",
    "echo_handler = MessageHandler(Filters.text, handler)\n",
    "dispatcher.add_handler(echo_handler)\n"
   ]
  },
  {
   "cell_type": "code",
   "execution_count": null,
   "metadata": {},
   "outputs": [],
   "source": []
  }
 ],
 "metadata": {
  "kernelspec": {
   "display_name": "Python 3.10.4 ('study')",
   "language": "python",
   "name": "python3"
  },
  "language_info": {
   "codemirror_mode": {
    "name": "ipython",
    "version": 3
   },
   "file_extension": ".py",
   "mimetype": "text/x-python",
   "name": "python",
   "nbconvert_exporter": "python",
   "pygments_lexer": "ipython3",
   "version": "3.10.4"
  },
  "orig_nbformat": 4,
  "vscode": {
   "interpreter": {
    "hash": "cdb3408ddd590d3368dab592099dfbb7bb79f8272c754c134a9f1c06d64a117d"
   }
  }
 },
 "nbformat": 4,
 "nbformat_minor": 2
}
